Workbook
Name email_address_1639266202: 'Thư mời giảng'!$M$1

Sheet KeHoach_HKI_25-26
E1: KẾ HOẠCH ĐÀO TẠO HỌC KỲ III
A5: A.Mục tiêu trong kỳ:
A7: B.Dự kiến lịch học tập trong học kỳ:
A9: KHOÁ | B9: KỲ | C9: SỐ LỚP | D9: SỐ SV | F9: Tháng 05 | J9: Tháng 06 | O9: Tháng 07 | S9: Tháng 08
F11: T1 | G11: T2 | H11: T3 | I11: T4 | J11: T5 | K11: T6 | L11: T7 | M11: T8 | N11: T9 | O11: T10 | P11: T11 | Q11: T12 | R11: T13 | S11: T14 | T11: T15 | U11: T16 | V11: T17
A12: 2023 | B12: 6 | C12: =COUNTIF('KHĐT'!$B$4:$B$520,A12) -> 0 | D12: =SUMIF('KHĐT'!$B$4:$B$476,#REF!,'KHĐT'!$F$4:$F476) -> #N/A | G12: x | H12: x | I12: x | J12: x | K12: x | L12: x | M12: x | N12: x | O12: x | P12: x | Q12: x | R12: x | S12: x | T12: T | U12: T | V12: N
A13: 2024 | B13: 3 | C13: =COUNTIF('KHĐT'!$B$4:$B$520,A13) -> 225 | D13: =SUMIF('KHĐT'!$B$4:$B$476,A12,'KHĐT'!$F$4:$F478) -> #N/A | G13: x | H13: x | I13: x | J13: x | K13: x | L13: x | M13: x | N13: x | O13: x | P13: x | Q13: x | R13: x | S13: x | T13: T | U13: T | V13: N
A14: Tổng/ Total | C14: =SUM(C12:C13) -> 225 | D14: =SUM(D12:D13) -> #N/A
C16: Trong đó: | D16: x – học; T – Thi; N: nghỉ học kỳ, nghỉ hè, nghỉ Tết AL; DT: dự trữ
A20: .Dự kiến lịch học tập trong học kỳ/ Estimated Schedule:
A22: TT | B22: Mã môn | C22: Tên môn | D22: SL ước dùng | E22: Hệ số | F22: Số SV max/lớp | G22: Tổng giờ/môn | H22: Số GV cần theo kế hoạch lớp/ ngành | I22: Tổng số lớp môn tối ưu theo số sv | J22: Số lớp đang cần triển khai(vật lý) | K22: Số lớp triển khai theo thực tế | L22: NGành | M22: Tổng số giờ | N22: Tên giáo trình
B23: Kỳ
B24: Số SV
B25: Số lớp
B26: Số môn | E26: 0 | F26: 0 | G26: 0 | H26: 0 | I26: 0 | K26: 0 | L26: 0 | M26: 0 | N26: 0
A27: A | B27: B | C27: C | D27: 1 | E27: G | F27: H | G27: I | H27: J | I27: 0 | K27: 0 | L27: K | M27: L | N27: M
A28: 1 | D28: =SUMIFS('KHĐT'!$G:$G,'KHĐT'!$H:$H,B28) -> 0 | E28: 1 | F28: =ThamSo!$B$2 -> 38 | G28: =VLOOKUP(C28,'KHĐT'!$I$2:$K$534,3,0) -> #N/A | H28: =IF(D28=0,0,IF(D28<F28,1,ROUND(D28/F28,1))) -> 0 | I28: =IF(D28=0,0,IF(D28<F28,1,ROUND(D28/F28,1))) -> 0 | J28: =COUNTIF('KHĐT'!$I$2:$I$534,C28) -> 0 | K28: =COUNTIF(TKB_HK2_Moi_Giang!G3:G27,C28) -> 0 | L28: =if(K28<=I28,"Ok","") -> Ok | M28: =G28*K28 -> #N/A
A29: 2 | D29: =SUMIFS('KHĐT'!$G:$G,'KHĐT'!$H:$H,B29) -> 0 | E29: 1 | F29: =ThamSo!$B$2 -> 38 | G29: =VLOOKUP(C29,'KHĐT'!$I$2:$K$534,3,0) -> #N/A | H29: =IF(D29=0,0,IF(D29<F29,1,ROUND(D29/F29,1))) -> 0 | I29: =IF(D29=0,0,IF(D29<F29,1,ROUND(D29/F29,1))) -> 0 | J29: =COUNTIF('KHĐT'!$I$2:$I$534,C29) -> 0 | K29: =COUNTIF(TKB_HK2_Moi_Giang!G933,C29) -> 0 | L29: =if(K29<=I29,"Ok","") -> Ok | M29: =G29*K29 -> #N/A
A30: 3 | D30: =SUMIFS('KHĐT'!$G:$G,'KHĐT'!$H:$H,B30) -> 0 | E30: 1 | F30: =ThamSo!$B$2 -> 38 | G30: =VLOOKUP(C30,'KHĐT'!$I$2:$K$534,3,0) -> #N/A | H30: =IF(D30=0,0,IF(D30<F30,1,ROUND(D30/F30,1))) -> 0 | I30: =IF(D30=0,0,IF(D30<F30,1,ROUND(D30/F30,1))) -> 0 | J30: =COUNTIF('KHĐT'!$I$2:$I$534,C30) -> 0 | K30: =COUNTIF(TKB_HK2_Moi_Giang!G3:G933,C30) -> 0 | L30: =if(K30<=I30,"Ok","") -> Ok | M30: =G30*K30 -> #N/A
A31: 4 | D31: =SUMIFS('KHĐT'!$G:$G,'KHĐT'!$H:$H,B31) -> 0 | E31: 1 | F31: =ThamSo!$B$2 -> 38 | G31: =VLOOKUP(C31,'KHĐT'!$I$2:$K$534,3,0) -> #N/A | H31: =IF(D31=0,0,IF(D31<F31,1,ROUND(D31/F31,1))) -> 0 | I31: =IF(D31=0,0,IF(D31<F31,1,ROUND(D31/F31,1))) -> 0 | J31: =COUNTIF('KHĐT'!$I$2:$I$534,C31) -> 0 | K31: =COUNTIF(TKB_HK2_Moi_Giang!G933,C31) -> 0 | L31: =if(K31<=I31,"Ok","") -> Ok | M31: =G31*K31 -> #N/A
A32: 5 | D32: =SUMIFS('KHĐT'!$G:$G,'KHĐT'!$H:$H,B32) -> 0 | E32: 1 | F32: =ThamSo!$B$2 -> 38 | G32: =VLOOKUP(C32,'KHĐT'!$I$2:$K$534,3,0) -> #N/A | H32: =IF(D32=0,0,IF(D32<F32,1,ROUND(D32/F32,1))) -> 0 | I32: =IF(D32=0,0,IF(D32<F32,1,ROUND(D32/F32,1))) -> 0 | J32: =COUNTIF('KHĐT'!$I$2:$I$534,C32) -> 0 | K32: =COUNTIF(TKB_HK2_Moi_Giang!G933,C32) -> 0 | L32: =if(K32<=I32,"Ok","") -> Ok | M32: =G32*K32 -> #N/A
A33: 6 | D33: =SUMIFS('KHĐT'!$G:$G,'KHĐT'!$H:$H,B33) -> 0 | E33: 1 | F33: =ThamSo!$B$2 -> 38 | G33: =VLOOKUP(C33,'KHĐT'!$I$2:$K$534,3,0) -> #N/A | H33: =IF(D33=0,0,IF(D33<F33,1,ROUND(D33/F33,1))) -> 0 | I33: =IF(D33=0,0,IF(D33<F33,1,ROUND(D33/F33,1))) -> 0 | J33: =COUNTIF('KHĐT'!$I$2:$I$534,C33) -> 0 | K33: =COUNTIF(TKB_HK2_Moi_Giang!G3:G933,C33) -> 0 | L33: =if(K33<=I33,"Ok","") -> Ok | M33: =G33*K33 -> #N/A
A34: 7 | D34: =SUMIFS('KHĐT'!$G:$G,'KHĐT'!$H:$H,B34) -> 0 | E34: 1 | F34: =ThamSo!$B$2 -> 38 | G34: =VLOOKUP(C34,'KHĐT'!$I$2:$K$534,3,0) -> #N/A | H34: =IF(D34=0,0,IF(D34<F34,1,ROUND(D34/F34,1))) -> 0 | I34: =IF(D34=0,0,IF(D34<F34,1,ROUND(D34/F34,1))) -> 0 | J34: =COUNTIF('KHĐT'!$I$2:$I$534,C34) -> 0 | K34: =COUNTIF(TKB_HK2_Moi_Giang!G3:G933,C34) -> 0 | L34: =if(K34<=I34,"Ok","") -> Ok | M34: =G34*K34 -> #N/A
A35: 8 | D35: =SUMIFS('KHĐT'!$G:$G,'KHĐT'!$H:$H,B35) -> 0 | E35: 1 | F35: =ThamSo!$B$2 -> 38 | G35: =VLOOKUP(C35,'KHĐT'!$I$2:$K$534,3,0) -> #N/A | H35: =IF(D35=0,0,IF(D35<F35,1,ROUND(D35/F35,1))) -> 0 | I35: =IF(D35=0,0,IF(D35<F35,1,ROUND(D35/F35,1))) -> 0 | J35: =COUNTIF('KHĐT'!$I$2:$I$534,C35) -> 0 | K35: =COUNTIF(TKB_HK2_Moi_Giang!G3:G933,C35) -> 0 | L35: =if(K35<=I35,"Ok","") -> Ok | M35: =G35*K35 -> #N/A
A36: 9 | D36: =SUMIFS('KHĐT'!$G:$G,'KHĐT'!$H:$H,B36) -> 0 | E36: 1 | F36: =ThamSo!$B$2 -> 38 | G36: =VLOOKUP(C36,'KHĐT'!$I$2:$K$534,3,0) -> #N/A | H36: =IF(D36=0,0,IF(D36<F36,1,ROUND(D36/F36,1))) -> 0 | I36: =IF(D36=0,0,IF(D36<F36,1,ROUND(D36/F36,1))) -> 0 | J36: =COUNTIF('KHĐT'!$I$2:$I$534,C36) -> 0 | K36: =COUNTIF(TKB_HK2_Moi_Giang!G928:G933,C36) -> 0 | L36: =if(K36<=I36,"Ok","") -> Ok | M36: =G36*K36 -> #N/A
A37: 10 | D37: =SUMIFS('KHĐT'!$G:$G,'KHĐT'!$H:$H,B37) -> 0 | E37: 1 | F37: =ThamSo!$B$2 -> 38 | G37: =VLOOKUP(C37,'KHĐT'!$I$2:$K$534,3,0) -> #N/A | H37: =IF(D37=0,0,IF(D37<F37,1,ROUND(D37/F37,1))) -> 0 | I37: =IF(D37=0,0,IF(D37<F37,1,ROUND(D37/F37,1))) -> 0 | J37: =COUNTIF('KHĐT'!$I$2:$I$534,C37) -> 0 | K37: =COUNTIF(TKB_HK2_Moi_Giang!G928:G933,C37) -> 0 | L37: =if(K37<=I37,"Ok","") -> Ok | M37: =G37*K37 -> #N/A
A38: 11 | D38: =SUMIFS('KHĐT'!$G:$G,'KHĐT'!$H:$H,B38) -> 0 | E38: 1 | F38: =ThamSo!$B$2 -> 38 | G38: =VLOOKUP(C38,'KHĐT'!$I$2:$K$534,3,0) -> #N/A | H38: =IF(D38=0,0,IF(D38<F38,1,ROUND(D38/F38,1))) -> 0 | I38: =IF(D38=0,0,IF(D38<F38,1,ROUND(D38/F38,1))) -> 0 | J38: =COUNTIF('KHĐT'!$I$2:$I$534,C38) -> 0 | K38: =COUNTIF(TKB_HK2_Moi_Giang!G928:G933,C38) -> 0 | L38: =if(K38<=I38,"Ok","") -> Ok | M38: =G38*K38 -> #N/A
A39: 12 | D39: =SUMIFS('KHĐT'!$G:$G,'KHĐT'!$H:$H,B39) -> 0 | E39: 1 | F39: =ThamSo!$B$2 -> 38 | G39: =VLOOKUP(C39,'KHĐT'!$I$2:$K$534,3,0) -> #N/A | H39: =IF(D39=0,0,IF(D39<F39,1,ROUND(D39/F39,1))) -> 0 | I39: =IF(D39=0,0,IF(D39<F39,1,ROUND(D39/F39,1))) -> 0 | J39: =COUNTIF('KHĐT'!$I$2:$I$534,C39) -> 0 | K39: =COUNTIF(TKB_HK2_Moi_Giang!G928:G933,C39) -> 0 | L39: =if(K39<=I39,"Ok","") -> Ok | M39: =G39*K39 -> #N/A
A40: 13 | D40: =SUMIFS('KHĐT'!$G:$G,'KHĐT'!$H:$H,B40) -> 0 | E40: 1 | F40: =ThamSo!$B$2 -> 38 | G40: =VLOOKUP(C40,'KHĐT'!$I$2:$K$534,3,0) -> #N/A | H40: =IF(D40=0,0,IF(D40<F40,1,ROUND(D40/F40,1))) -> 0 | I40: =IF(D40=0,0,IF(D40<F40,1,ROUND(D40/F40,1))) -> 0 | J40: =COUNTIF('KHĐT'!$I$2:$I$534,C40) -> 0 | K40: =COUNTIF(TKB_HK2_Moi_Giang!G928:G933,C40) -> 0 | L40: =if(K40<=I40,"Ok","") -> Ok | M40: =G40*K40 -> #N/A
A41: 14 | D41: =SUMIFS('KHĐT'!$G:$G,'KHĐT'!$H:$H,B41) -> 0 | E41: 1 | F41: =ThamSo!$B$2 -> 38 | G41: =VLOOKUP(C41,'KHĐT'!$I$2:$K$534,3,0) -> #N/A | H41: =IF(D41=0,0,IF(D41<F41,1,ROUND(D41/F41,1))) -> 0 | I41: =IF(D41=0,0,IF(D41<F41,1,ROUND(D41/F41,1))) -> 0 | J41: =COUNTIF('KHĐT'!$I$2:$I$534,C41) -> 0 | K41: =COUNTIF(TKB_HK2_Moi_Giang!G928:G933,C41) -> 0 | L41: =if(K41<=I41,"Ok","") -> Ok | M41: =G41*K41 -> #N/A
A42: 15 | D42: =SUMIFS('KHĐT'!$G:$G,'KHĐT'!$H:$H,B42) -> 0 | E42: 1 | F42: =ThamSo!$B$2 -> 38 | G42: =VLOOKUP(C42,'KHĐT'!$I$2:$K$534,3,0) -> #N/A | H42: =IF(D42=0,0,IF(D42<F42,1,ROUND(D42/F42,1))) -> 0 | I42: =IF(D42=0,0,IF(D42<F42,1,ROUND(D42/F42,1))) -> 0 | J42: =COUNTIF('KHĐT'!$I$2:$I$534,C42) -> 0 | K42: =COUNTIF(TKB_HK2_Moi_Giang!G928:G933,C42) -> 0 | L42: =if(K42<=I42,"Ok","") -> Ok | M42: =G42*K42 -> #N/A
A43: 16 | D43: =SUMIFS('KHĐT'!$G:$G,'KHĐT'!$H:$H,B43) -> 0 | E43: 1 | F43: =ThamSo!$B$2 -> 38 | G43: =VLOOKUP(C43,'KHĐT'!$I$2:$K$534,3,0) -> #N/A | H43: =IF(D43=0,0,IF(D43<F43,1,ROUND(D43/F43,1))) -> 0 | I43: =IF(D43=0,0,IF(D43<F43,1,ROUND(D43/F43,1))) -> 0 | J43: =COUNTIF('KHĐT'!$I$2:$I$534,C43) -> 0 | K43: =COUNTIF(TKB_HK2_Moi_Giang!G928:G933,C43) -> 0 | L43: =if(K43<=I43,"Ok","") -> Ok | M43: =G43*K43 -> #N/A
A44: 17 | D44: =SUMIFS('KHĐT'!$G:$G,'KHĐT'!$H:$H,B44) -> 0 | E44: 1 | F44: =ThamSo!$B$2 -> 38 | G44: =VLOOKUP(C44,'KHĐT'!$I$2:$K$534,3,0) -> #N/A | H44: =IF(D44=0,0,IF(D44<F44,1,ROUND(D44/F44,1))) -> 0 | I44: =IF(D44=0,0,IF(D44<F44,1,ROUND(D44/F44,1))) -> 0 | J44: =COUNTIF('KHĐT'!$I$2:$I$534,C44) -> 0 | K44: =COUNTIF(TKB_HK2_Moi_Giang!G928:G933,C44) -> 0 | L44: =if(K44<=I44,"Ok","") -> Ok | M44: =G44*K44 -> #N/A
A45: 18 | D45: =SUMIFS('KHĐT'!$G:$G,'KHĐT'!$H:$H,B45) -> 0 | E45: 1 | F45: =ThamSo!$B$2 -> 38 | G45: =VLOOKUP(C45,'KHĐT'!$I$2:$K$534,3,0) -> #N/A | H45: =IF(D45=0,0,IF(D45<F45,1,ROUND(D45/F45,1))) -> 0 | I45: =IF(D45=0,0,IF(D45<F45,1,ROUND(D45/F45,1))) -> 0 | J45: =COUNTIF('KHĐT'!$I$2:$I$534,C45) -> 0 | K45: =COUNTIF(TKB_HK2_Moi_Giang!G928:G933,C45) -> 0 | L45: =if(K45<=I45,"Ok","") -> Ok | M45: =G45*K45 -> #N/A
A46: 19 | D46: =SUMIFS('KHĐT'!$G:$G,'KHĐT'!$H:$H,B46) -> 0 | E46: 1 | F46: =ThamSo!$B$2 -> 38 | G46: =VLOOKUP(C46,'KHĐT'!$I$2:$K$534,3,0) -> #N/A | H46: =IF(D46=0,0,IF(D46<F46,1,ROUND(D46/F46,1))) -> 0 | I46: =IF(D46=0,0,IF(D46<F46,1,ROUND(D46/F46,1))) -> 0 | J46: =COUNTIF('KHĐT'!$I$2:$I$534,C46) -> 0 | K46: =COUNTIF(TKB_HK2_Moi_Giang!G928:G933,C46) -> 0 | L46: =if(K46<=I46,"Ok","") -> Ok | M46: =G46*K46 -> #N/A
A47: 20 | D47: =SUMIFS('KHĐT'!$G:$G,'KHĐT'!$H:$H,B47) -> 0 | E47: 1 | F47: =ThamSo!$B$2 -> 38 | G47: =VLOOKUP(C47,'KHĐT'!$I$2:$K$534,3,0) -> #N/A | H47: =IF(D47=0,0,IF(D47<F47,1,ROUND(D47/F47,1))) -> 0 | I47: =IF(D47=0,0,IF(D47<F47,1,ROUND(D47/F47,1))) -> 0 | J47: =COUNTIF('KHĐT'!$I$2:$I$534,C47) -> 0 | K47: =COUNTIF(TKB_HK2_Moi_Giang!G928:G933,C47) -> 0 | L47: =if(K47<=I47,"Ok","") -> Ok | M47: =G47*K47 -> #N/A
A48: 21 | D48: =SUMIFS('KHĐT'!$G:$G,'KHĐT'!$H:$H,B48) -> 0 | E48: 1 | F48: =ThamSo!$B$2 -> 38 | G48: =VLOOKUP(C48,'KHĐT'!$I$2:$K$534,3,0) -> #N/A | H48: =IF(D48=0,0,IF(D48<F48,1,ROUND(D48/F48,1))) -> 0 | I48: =IF(D48=0,0,IF(D48<F48,1,ROUND(D48/F48,1))) -> 0 | J48: =COUNTIF('KHĐT'!$I$2:$I$534,C48) -> 0 | K48: =COUNTIF(TKB_HK2_Moi_Giang!G928:G933,C48) -> 0 | L48: =if(K48<=I48,"Ok","") -> Ok | M48: =G48*K48 -> #N/A
A49: 22 | D49: =SUMIFS('KHĐT'!$G:$G,'KHĐT'!$H:$H,B49) -> 0 | E49: 1 | F49: =ThamSo!$B$2 -> 38 | G49: =VLOOKUP(C49,'KHĐT'!$I$2:$K$534,3,0) -> #N/A | H49: =IF(D49=0,0,IF(D49<F49,1,ROUND(D49/F49,1))) -> 0 | I49: =IF(D49=0,0,IF(D49<F49,1,ROUND(D49/F49,1))) -> 0 | J49: =COUNTIF('KHĐT'!$I$2:$I$534,C49) -> 0 | K49: =COUNTIF(TKB_HK2_Moi_Giang!G928:G933,C49) -> 0 | L49: =if(K49<=I49,"Ok","") -> Ok | M49: =G49*K49 -> #N/A
A50: 23 | D50: =SUMIFS('KHĐT'!$G:$G,'KHĐT'!$H:$H,B50) -> 0 | E50: 1 | F50: =ThamSo!$B$2 -> 38 | G50: =VLOOKUP(C50,'KHĐT'!$I$2:$K$534,3,0) -> #N/A | H50: =IF(D50=0,0,IF(D50<F50,1,ROUND(D50/F50,1))) -> 0 | I50: =IF(D50=0,0,IF(D50<F50,1,ROUND(D50/F50,1))) -> 0 | J50: =COUNTIF('KHĐT'!$I$2:$I$534,C50) -> 0 | K50: =COUNTIF(TKB_HK2_Moi_Giang!G928:G933,C50) -> 0 | L50: =if(K50<=I50,"Ok","") -> Ok | M50: =G50*K50 -> #N/A
A51: 24 | D51: =SUMIFS('KHĐT'!$G:$G,'KHĐT'!$H:$H,B51) -> 0 | E51: 1 | F51: =ThamSo!$B$2 -> 38 | G51: =VLOOKUP(C51,'KHĐT'!$I$2:$K$534,3,0) -> #N/A | H51: =IF(D51=0,0,IF(D51<F51,1,ROUND(D51/F51,1))) -> 0 | I51: =IF(D51=0,0,IF(D51<F51,1,ROUND(D51/F51,1))) -> 0 | J51: =COUNTIF('KHĐT'!$I$2:$I$534,C51) -> 0 | K51: =COUNTIF(TKB_HK2_Moi_Giang!G928:G933,C51) -> 0 | L51: =if(K51<=I51,"Ok","") -> Ok | M51: =G51*K51 -> #N/A
...

Sheet ThongKe_GV
E1: 2 | F1: 3 | G1: 4 | H1: 5 | I1: 6 | J1: 7 | K1: 2 | L1: 3 | M1: 4 | N1: 5 | O1: 6 | P1: 7 | Q1: 2 | R1: 3 | S1: 4 | T1: 5 | U1: 6 | V1: 7 | W1: 2 | X1: 3 | Y1: 4 | Z1: 5 | AA1: 6 | AB1: 7
A2: Khoa/ Ngành | B2: MA GV | C2: Họ và Tên | D2: Email | E2: 0.32291667 | F2: 0.32291667 | G2: 0.32291667 | H2: 0.32291667 | I2: 0.32291667 | J2: 0.32291667 | K2: 0.39583333 | L2: 0.39583333 | M2: 0.39583333 | N2: 0.39583333 | O2: 0.39583333 | P2: 0.39583333 | Q2: 0.54166667 | R2: 0.54166667 | S2: 0.54166667 | T2: 0.54166667 | U2: 0.54166667 | V2: 0.54166667 | W2: 0.64583333 | X2: 0.64583333 | Y2: 0.64583333 | Z2: 0.64583333 | AA2: 0.64583333 | AB2: 0.64583333
A3: =IF(MID(B3,4,1)="Q","Quản trị",IF(MID(B3,4,1)="T","Thiết kế",IF(MID(B3,4,1)="N","Ngoại ngữ",IF(MID(B3,4,1)="C","Công nghệ",IF(MID(B3,4,1)="Y","Y dược",IF(MID(B3,4,1)="V","Văn hóa","")))))) -> Quản trị | B3: TG-QT079 | C3: Nguyễn Minh Hiến | D3: hien.nguyen4@caodangvietmy.edu.vn | E3: =IF(COUNTIFS(TKB_HK2_Moi_Giang!$S:$S,ThongKe_GV!$C3,TKB_HK2_Moi_Giang!$K:$K,ThongKe_GV!E$1,TKB_HK2_Moi_Giang!$L:$L,ThongKe_GV!E$2)>0,"X","") | F3: =IF(COUNTIFS(TKB_HK2_Moi_Giang!$S:$S,ThongKe_GV!$C3,TKB_HK2_Moi_Giang!$K:$K,ThongKe_GV!F$1,TKB_HK2_Moi_Giang!$L:$L,ThongKe_GV!F$2)>0,"X","") -> X | G3: =IF(COUNTIFS(TKB_HK2_Moi_Giang!$S:$S,ThongKe_GV!$C3,TKB_HK2_Moi_Giang!$K:$K,ThongKe_GV!G$1,TKB_HK2_Moi_Giang!$L:$L,ThongKe_GV!G$2)>0,"X","") -> X | H3: =IF(COUNTIFS(TKB_HK2_Moi_Giang!$S:$S,ThongKe_GV!$C3,TKB_HK2_Moi_Giang!$K:$K,ThongKe_GV!H$1,TKB_HK2_Moi_Giang!$L:$L,ThongKe_GV!H$2)>0,"X","") -> X | I3: =IF(COUNTIFS(TKB_HK2_Moi_Giang!$S:$S,ThongKe_GV!$C3,TKB_HK2_Moi_Giang!$K:$K,ThongKe_GV!I$1,TKB_HK2_Moi_Giang!$L:$L,ThongKe_GV!I$2)>0,"X","") | J3: =IF(COUNTIFS(TKB_HK2_Moi_Giang!$S:$S,ThongKe_GV!$C3,TKB_HK2_Moi_Giang!$K:$K,ThongKe_GV!J$1,TKB_HK2_Moi_Giang!$L:$L,ThongKe_GV!J$2)>0,"X","") | K3: =IF(COUNTIFS(TKB_HK2_Moi_Giang!$S:$S,ThongKe_GV!$C3,TKB_HK2_Moi_Giang!$K:$K,ThongKe_GV!K$1,TKB_HK2_Moi_Giang!$L:$L,ThongKe_GV!K$2)>0,"X","") | L3: =IF(COUNTIFS(TKB_HK2_Moi_Giang!$S:$S,ThongKe_GV!$C3,TKB_HK2_Moi_Giang!$K:$K,ThongKe_GV!L$1,TKB_HK2_Moi_Giang!$L:$L,ThongKe_GV!L$2)>0,"X","") | ... AB3: =IF(COUNTIFS(TKB_HK2_Moi_Giang!$S:$S,ThongKe_GV!$C3,TKB_HK2_Moi_Giang!$K:$K,ThongKe_GV!AB$1,TKB_HK2_Moi_Giang!$L:$L,ThongKe_GV!AB$2)>0,"X","")
A4: =IF(MID(B4,4,1)="Q","Quản trị",IF(MID(B4,4,1)="T","Thiết kế",IF(MID(B4,4,1)="N","Ngoại ngữ",IF(MID(B4,4,1)="C","Công nghệ",IF(MID(B4,4,1)="Y","Y dược",IF(MID(B4,4,1)="V","Văn hóa","")))))) -> Công nghệ | B4: TG-CNTT12 | C4: Lữ Thị Cẩm Tú | D4: tu05dhth1@gmail.com | E4: =IF(COUNTIFS(TKB_HK2_Moi_Giang!$S:$S,ThongKe_GV!$C4,TKB_HK2_Moi_Giang!$K:$K,ThongKe_GV!E$1,TKB_HK2_Moi_Giang!$L:$L,ThongKe_GV!E$2)>0,"X","") | F4: =IF(COUNTIFS(TKB_HK2_Moi_Giang!$S:$S,ThongKe_GV!$C4,TKB_HK2_Moi_Giang!$K:$K,ThongKe_GV!F$1,TKB_HK2_Moi_Giang!$L:$L,ThongKe_GV!F$2)>0,"X","") | G4: =IF(COUNTIFS(TKB_HK2_Moi_Giang!$S:$S,ThongKe_GV!$C4,TKB_HK2_Moi_Giang!$K:$K,ThongKe_GV!G$1,TKB_HK2_Moi_Giang!$L:$L,ThongKe_GV!G$2)>0,"X","") | H4: =IF(COUNTIFS(TKB_HK2_Moi_Giang!$S:$S,ThongKe_GV!$C4,TKB_HK2_Moi_Giang!$K:$K,ThongKe_GV!H$1,TKB_HK2_Moi_Giang!$L:$L,ThongKe_GV!H$2)>0,"X","") | I4: =IF(COUNTIFS(TKB_HK2_Moi_Giang!$S:$S,ThongKe_GV!$C4,TKB_HK2_Moi_Giang!$K:$K,ThongKe_GV!I$1,TKB_HK2_Moi_Giang!$L:$L,ThongKe_GV!I$2)>0,"X","") | J4: =IF(COUNTIFS(TKB_HK2_Moi_Giang!$S:$S,ThongKe_GV!$C4,TKB_HK2_Moi_Giang!$K:$K,ThongKe_GV!J$1,TKB_HK2_Moi_Giang!$L:$L,ThongKe_GV!J$2)>0,"X","") | K4: =IF(COUNTIFS(TKB_HK2_Moi_Giang!$S:$S,ThongKe_GV!$C4,TKB_HK2_Moi_Giang!$K:$K,ThongKe_GV!K$1,TKB_HK2_Moi_Giang!$L:$L,ThongKe_GV!K$2)>0,"X","") | L4: =IF(COUNTIFS(TKB_HK2_Moi_Giang!$S:$S,ThongKe_GV!$C4,TKB_HK2_Moi_Giang!$K:$K,ThongKe_GV!L$1,TKB_HK2_Moi_Giang!$L:$L,ThongKe_GV!L$2)>0,"X","") | ... AB4: =IF(COUNTIFS(TKB_HK2_Moi_Giang!$S:$S,ThongKe_GV!$C4,TKB_HK2_Moi_Giang!$K:$K,ThongKe_GV!AB$1,TKB_HK2_Moi_Giang!$L:$L,ThongKe_GV!AB$2)>0,"X","")
A5: =IF(MID(B5,4,1)="Q","Quản trị",IF(MID(B5,4,1)="T","Thiết kế",IF(MID(B5,4,1)="N","Ngoại ngữ",IF(MID(B5,4,1)="C","Công nghệ",IF(MID(B5,4,1)="Y","Y dược",IF(MID(B5,4,1)="V","Văn hóa","")))))) -> Quản trị | B5: TG-QT099 | C5: Đào Út Quỳnh | D5: daoutquynh.brandstrategy@gmail.com | E5: =IF(COUNTIFS(TKB_HK2_Moi_Giang!$S:$S,ThongKe_GV!$C5,TKB_HK2_Moi_Giang!$K:$K,ThongKe_GV!E$1,TKB_HK2_Moi_Giang!$L:$L,ThongKe_GV!E$2)>0,"X","") | F5: =IF(COUNTIFS(TKB_HK2_Moi_Giang!$S:$S,ThongKe_GV!$C5,TKB_HK2_Moi_Giang!$K:$K,ThongKe_GV!F$1,TKB_HK2_Moi_Giang!$L:$L,ThongKe_GV!F$2)>0,"X","") | G5: =IF(COUNTIFS(TKB_HK2_Moi_Giang!$S:$S,ThongKe_GV!$C5,TKB_HK2_Moi_Giang!$K:$K,ThongKe_GV!G$1,TKB_HK2_Moi_Giang!$L:$L,ThongKe_GV!G$2)>0,"X","") | H5: =IF(COUNTIFS(TKB_HK2_Moi_Giang!$S:$S,ThongKe_GV!$C5,TKB_HK2_Moi_Giang!$K:$K,ThongKe_GV!H$1,TKB_HK2_Moi_Giang!$L:$L,ThongKe_GV!H$2)>0,"X","") | I5: =IF(COUNTIFS(TKB_HK2_Moi_Giang!$S:$S,ThongKe_GV!$C5,TKB_HK2_Moi_Giang!$K:$K,ThongKe_GV!I$1,TKB_HK2_Moi_Giang!$L:$L,ThongKe_GV!I$2)>0,"X","") | J5: =IF(COUNTIFS(TKB_HK2_Moi_Giang!$S:$S,ThongKe_GV!$C5,TKB_HK2_Moi_Giang!$K:$K,ThongKe_GV!J$1,TKB_HK2_Moi_Giang!$L:$L,ThongKe_GV!J$2)>0,"X","") | K5: =IF(COUNTIFS(TKB_HK2_Moi_Giang!$S:$S,ThongKe_GV!$C5,TKB_HK2_Moi_Giang!$K:$K,ThongKe_GV!K$1,TKB_HK2_Moi_Giang!$L:$L,ThongKe_GV!K$2)>0,"X","") | L5: =IF(COUNTIFS(TKB_HK2_Moi_Giang!$S:$S,ThongKe_GV!$C5,TKB_HK2_Moi_Giang!$K:$K,ThongKe_GV!L$1,TKB_HK2_Moi_Giang!$L:$L,ThongKe_GV!L$2)>0,"X","") | ... AB5: =IF(COUNTIFS(TKB_HK2_Moi_Giang!$S:$S,ThongKe_GV!$C5,TKB_HK2_Moi_Giang!$K:$K,ThongKe_GV!AB$1,TKB_HK2_Moi_Giang!$L:$L,ThongKe_GV!AB$2)>0,"X","")
A6: =IF(MID(B6,4,1)="Q","Quản trị",IF(MID(B6,4,1)="T","Thiết kế",IF(MID(B6,4,1)="N","Ngoại ngữ",IF(MID(B6,4,1)="C","Công nghệ",IF(MID(B6,4,1)="Y","Y dược",IF(MID(B6,4,1)="V","Văn hóa","")))))) -> Ngoại ngữ | B6: TG-NN011 | C6: Trần Thị Thanh Hằng | D6: thanhhang161298@gmail.com | F6: =IF(COUNTIFS(TKB_HK2_Moi_Giang!$S:$S,ThongKe_GV!$C6,TKB_HK2_Moi_Giang!$K:$K,ThongKe_GV!F$1,TKB_HK2_Moi_Giang!$L:$L,ThongKe_GV!F$2)>0,"X","") | G6: =IF(COUNTIFS(TKB_HK2_Moi_Giang!$S:$S,ThongKe_GV!$C6,TKB_HK2_Moi_Giang!$K:$K,ThongKe_GV!G$1,TKB_HK2_Moi_Giang!$L:$L,ThongKe_GV!G$2)>0,"X","") | H6: =IF(COUNTIFS(TKB_HK2_Moi_Giang!$S:$S,ThongKe_GV!$C6,TKB_HK2_Moi_Giang!$K:$K,ThongKe_GV!H$1,TKB_HK2_Moi_Giang!$L:$L,ThongKe_GV!H$2)>0,"X","") | I6: =IF(COUNTIFS(TKB_HK2_Moi_Giang!$S:$S,ThongKe_GV!$C6,TKB_HK2_Moi_Giang!$K:$K,ThongKe_GV!I$1,TKB_HK2_Moi_Giang!$L:$L,ThongKe_GV!I$2)>0,"X","") | J6: =IF(COUNTIFS(TKB_HK2_Moi_Giang!$S:$S,ThongKe_GV!$C6,TKB_HK2_Moi_Giang!$K:$K,ThongKe_GV!J$1,TKB_HK2_Moi_Giang!$L:$L,ThongKe_GV!J$2)>0,"X","") | K6: =IF(COUNTIFS(TKB_HK2_Moi_Giang!$S:$S,ThongKe_GV!$C6,TKB_HK2_Moi_Giang!$K:$K,ThongKe_GV!K$1,TKB_HK2_Moi_Giang!$L:$L,ThongKe_GV!K$2)>0,"X","") | L6: =IF(COUNTIFS(TKB_HK2_Moi_Giang!$S:$S,ThongKe_GV!$C6,TKB_HK2_Moi_Giang!$K:$K,ThongKe_GV!L$1,TKB_HK2_Moi_Giang!$L:$L,ThongKe_GV!L$2)>0,"X","") | M6: =IF(COUNTIFS(TKB_HK2_Moi_Giang!$S:$S,ThongKe_GV!$C6,TKB_HK2_Moi_Giang!$K:$K,ThongKe_GV!M$1,TKB_HK2_Moi_Giang!$L:$L,ThongKe_GV!M$2)>0,"X","") | ... AB6: =IF(COUNTIFS(TKB_HK2_Moi_Giang!$S:$S,ThongKe_GV!$C6,TKB_HK2_Moi_Giang!$K:$K,ThongKe_GV!AB$1,TKB_HK2_Moi_Giang!$L:$L,ThongKe_GV!AB$2)>0,"X","")
A7: =IF(MID(B7,4,1)="Q","Quản trị",IF(MID(B7,4,1)="T","Thiết kế",IF(MID(B7,4,1)="N","Ngoại ngữ",IF(MID(B7,4,1)="C","Công nghệ",IF(MID(B7,4,1)="Y","Y dược",IF(MID(B7,4,1)="V","Văn hóa","")))))) -> Thiết kế | B7: TG-TK029 | C7: Phan Thành Sơn | D7: son.phan@caodangvietmy.edu.vn | E7: =IF(COUNTIFS(TKB_HK2_Moi_Giang!$S:$S,ThongKe_GV!$C7,TKB_HK2_Moi_Giang!$K:$K,ThongKe_GV!E$1,TKB_HK2_Moi_Giang!$L:$L,ThongKe_GV!E$2)>0,"X","") | F7: =IF(COUNTIFS(TKB_HK2_Moi_Giang!$S:$S,ThongKe_GV!$C7,TKB_HK2_Moi_Giang!$K:$K,ThongKe_GV!F$1,TKB_HK2_Moi_Giang!$L:$L,ThongKe_GV!F$2)>0,"X","") | G7: =IF(COUNTIFS(TKB_HK2_Moi_Giang!$S:$S,ThongKe_GV!$C7,TKB_HK2_Moi_Giang!$K:$K,ThongKe_GV!G$1,TKB_HK2_Moi_Giang!$L:$L,ThongKe_GV!G$2)>0,"X","") | H7: =IF(COUNTIFS(TKB_HK2_Moi_Giang!$S:$S,ThongKe_GV!$C7,TKB_HK2_Moi_Giang!$K:$K,ThongKe_GV!H$1,TKB_HK2_Moi_Giang!$L:$L,ThongKe_GV!H$2)>0,"X","") | I7: =IF(COUNTIFS(TKB_HK2_Moi_Giang!$S:$S,ThongKe_GV!$C7,TKB_HK2_Moi_Giang!$K:$K,ThongKe_GV!I$1,TKB_HK2_Moi_Giang!$L:$L,ThongKe_GV!I$2)>0,"X","") | J7: =IF(COUNTIFS(TKB_HK2_Moi_Giang!$S:$S,ThongKe_GV!$C7,TKB_HK2_Moi_Giang!$K:$K,ThongKe_GV!J$1,TKB_HK2_Moi_Giang!$L:$L,ThongKe_GV!J$2)>0,"X","") | K7: =IF(COUNTIFS(TKB_HK2_Moi_Giang!$S:$S,ThongKe_GV!$C7,TKB_HK2_Moi_Giang!$K:$K,ThongKe_GV!K$1,TKB_HK2_Moi_Giang!$L:$L,ThongKe_GV!K$2)>0,"X","") | L7: =IF(COUNTIFS(TKB_HK2_Moi_Giang!$S:$S,ThongKe_GV!$C7,TKB_HK2_Moi_Giang!$K:$K,ThongKe_GV!L$1,TKB_HK2_Moi_Giang!$L:$L,ThongKe_GV!L$2)>0,"X","") | ... AB7: =IF(COUNTIFS(TKB_HK2_Moi_Giang!$S:$S,ThongKe_GV!$C7,TKB_HK2_Moi_Giang!$K:$K,ThongKe_GV!AB$1,TKB_HK2_Moi_Giang!$L:$L,ThongKe_GV!AB$2)>0,"X","")
B8: TG-TN016 | C8: Nguyễn Thị Hoa | D8: nguyenhoa.253024@gmail.com | E8: =IF(COUNTIFS(TKB_HK2_Moi_Giang!$S:$S,ThongKe_GV!$C8,TKB_HK2_Moi_Giang!$K:$K,ThongKe_GV!E$1,TKB_HK2_Moi_Giang!$L:$L,ThongKe_GV!E$2)>0,"X","") | F8: =IF(COUNTIFS(TKB_HK2_Moi_Giang!$S:$S,ThongKe_GV!$C8,TKB_HK2_Moi_Giang!$K:$K,ThongKe_GV!F$1,TKB_HK2_Moi_Giang!$L:$L,ThongKe_GV!F$2)>0,"X","") | G8: =IF(COUNTIFS(TKB_HK2_Moi_Giang!$S:$S,ThongKe_GV!$C8,TKB_HK2_Moi_Giang!$K:$K,ThongKe_GV!G$1,TKB_HK2_Moi_Giang!$L:$L,ThongKe_GV!G$2)>0,"X","") | H8: =IF(COUNTIFS(TKB_HK2_Moi_Giang!$S:$S,ThongKe_GV!$C8,TKB_HK2_Moi_Giang!$K:$K,ThongKe_GV!H$1,TKB_HK2_Moi_Giang!$L:$L,ThongKe_GV!H$2)>0,"X","") | I8: =IF(COUNTIFS(TKB_HK2_Moi_Giang!$S:$S,ThongKe_GV!$C8,TKB_HK2_Moi_Giang!$K:$K,ThongKe_GV!I$1,TKB_HK2_Moi_Giang!$L:$L,ThongKe_GV!I$2)>0,"X","") | J8: =IF(COUNTIFS(TKB_HK2_Moi_Giang!$S:$S,ThongKe_GV!$C8,TKB_HK2_Moi_Giang!$K:$K,ThongKe_GV!J$1,TKB_HK2_Moi_Giang!$L:$L,ThongKe_GV!J$2)>0,"X","") | K8: =IF(COUNTIFS(TKB_HK2_Moi_Giang!$S:$S,ThongKe_GV!$C8,TKB_HK2_Moi_Giang!$K:$K,ThongKe_GV!K$1,TKB_HK2_Moi_Giang!$L:$L,ThongKe_GV!K$2)>0,"X","") | L8: =IF(COUNTIFS(TKB_HK2_Moi_Giang!$S:$S,ThongKe_GV!$C8,TKB_HK2_Moi_Giang!$K:$K,ThongKe_GV!L$1,TKB_HK2_Moi_Giang!$L:$L,ThongKe_GV!L$2)>0,"X","") | ... AB8: =IF(COUNTIFS(TKB_HK2_Moi_Giang!$S:$S,ThongKe_GV!$C8,TKB_HK2_Moi_Giang!$K:$K,ThongKe_GV!AB$1,TKB_HK2_Moi_Giang!$L:$L,ThongKe_GV!AB$2)>0,"X","")
A9: =IF(MID(B9,4,1)="Q","Quản trị",IF(MID(B9,4,1)="T","Thiết kế",IF(MID(B9,4,1)="N","Ngoại ngữ",IF(MID(B9,4,1)="C","Công nghệ",IF(MID(B9,4,1)="Y","Y dược",IF(MID(B9,4,1)="V","Văn hóa","")))))) -> Quản trị | B9: TG-QT101 | C9: Tô Thị Phương Thúy | D9: thuy.to@caodangvietmy.edu.vn | E9: =IF(COUNTIFS(TKB_HK2_Moi_Giang!$S:$S,ThongKe_GV!$C9,TKB_HK2_Moi_Giang!$K:$K,ThongKe_GV!E$1,TKB_HK2_Moi_Giang!$L:$L,ThongKe_GV!E$2)>0,"X","") | F9: =IF(COUNTIFS(TKB_HK2_Moi_Giang!$S:$S,ThongKe_GV!$C9,TKB_HK2_Moi_Giang!$K:$K,ThongKe_GV!F$1,TKB_HK2_Moi_Giang!$L:$L,ThongKe_GV!F$2)>0,"X","") | G9: =IF(COUNTIFS(TKB_HK2_Moi_Giang!$S:$S,ThongKe_GV!$C9,TKB_HK2_Moi_Giang!$K:$K,ThongKe_GV!G$1,TKB_HK2_Moi_Giang!$L:$L,ThongKe_GV!G$2)>0,"X","") | H9: =IF(COUNTIFS(TKB_HK2_Moi_Giang!$S:$S,ThongKe_GV!$C9,TKB_HK2_Moi_Giang!$K:$K,ThongKe_GV!H$1,TKB_HK2_Moi_Giang!$L:$L,ThongKe_GV!H$2)>0,"X","") | I9: =IF(COUNTIFS(TKB_HK2_Moi_Giang!$S:$S,ThongKe_GV!$C9,TKB_HK2_Moi_Giang!$K:$K,ThongKe_GV!I$1,TKB_HK2_Moi_Giang!$L:$L,ThongKe_GV!I$2)>0,"X","") | J9: =IF(COUNTIFS(TKB_HK2_Moi_Giang!$S:$S,ThongKe_GV!$C9,TKB_HK2_Moi_Giang!$K:$K,ThongKe_GV!J$1,TKB_HK2_Moi_Giang!$L:$L,ThongKe_GV!J$2)>0,"X","") | K9: =IF(COUNTIFS(TKB_HK2_Moi_Giang!$S:$S,ThongKe_GV!$C9,TKB_HK2_Moi_Giang!$K:$K,ThongKe_GV!K$1,TKB_HK2_Moi_Giang!$L:$L,ThongKe_GV!K$2)>0,"X","") | L9: =IF(COUNTIFS(TKB_HK2_Moi_Giang!$S:$S,ThongKe_GV!$C9,TKB_HK2_Moi_Giang!$K:$K,ThongKe_GV!L$1,TKB_HK2_Moi_Giang!$L:$L,ThongKe_GV!L$2)>0,"X","") | ... AB9: =IF(COUNTIFS(TKB_HK2_Moi_Giang!$S:$S,ThongKe_GV!$C9,TKB_HK2_Moi_Giang!$K:$K,ThongKe_GV!AB$1,TKB_HK2_Moi_Giang!$L:$L,ThongKe_GV!AB$2)>0,"X","")
A10: =IF(MID(B10,4,1)="Q","Quản trị",IF(MID(B10,4,1)="T","Thiết kế",IF(MID(B10,4,1)="N","Ngoại ngữ",IF(MID(B10,4,1)="C","Công nghệ",IF(MID(B10,4,1)="Y","Y dược",IF(MID(B10,4,1)="V","Văn hóa","")))))) -> Thiết kế | B10: TG-TK044 | C10: Lê Hoàng Nhật Minh | D10: ktk.dohoa16.hcm@caodangvietmy.edu.vn | E10: =IF(COUNTIFS(TKB_HK2_Moi_Giang!$S:$S,ThongKe_GV!$C10,TKB_HK2_Moi_Giang!$K:$K,ThongKe_GV!E$1,TKB_HK2_Moi_Giang!$L:$L,ThongKe_GV!E$2)>0,"X","") | F10: =IF(COUNTIFS(TKB_HK2_Moi_Giang!$S:$S,ThongKe_GV!$C10,TKB_HK2_Moi_Giang!$K:$K,ThongKe_GV!F$1,TKB_HK2_Moi_Giang!$L:$L,ThongKe_GV!F$2)>0,"X","") | G10: =IF(COUNTIFS(TKB_HK2_Moi_Giang!$S:$S,ThongKe_GV!$C10,TKB_HK2_Moi_Giang!$K:$K,ThongKe_GV!G$1,TKB_HK2_Moi_Giang!$L:$L,ThongKe_GV!G$2)>0,"X","") | H10: =IF(COUNTIFS(TKB_HK2_Moi_Giang!$S:$S,ThongKe_GV!$C10,TKB_HK2_Moi_Giang!$K:$K,ThongKe_GV!H$1,TKB_HK2_Moi_Giang!$L:$L,ThongKe_GV!H$2)>0,"X","") | I10: =IF(COUNTIFS(TKB_HK2_Moi_Giang!$S:$S,ThongKe_GV!$C10,TKB_HK2_Moi_Giang!$K:$K,ThongKe_GV!I$1,TKB_HK2_Moi_Giang!$L:$L,ThongKe_GV!I$2)>0,"X","") | J10: =IF(COUNTIFS(TKB_HK2_Moi_Giang!$S:$S,ThongKe_GV!$C10,TKB_HK2_Moi_Giang!$K:$K,ThongKe_GV!J$1,TKB_HK2_Moi_Giang!$L:$L,ThongKe_GV!J$2)>0,"X","") | K10: =IF(COUNTIFS(TKB_HK2_Moi_Giang!$S:$S,ThongKe_GV!$C10,TKB_HK2_Moi_Giang!$K:$K,ThongKe_GV!K$1,TKB_HK2_Moi_Giang!$L:$L,ThongKe_GV!K$2)>0,"X","") | L10: =IF(COUNTIFS(TKB_HK2_Moi_Giang!$S:$S,ThongKe_GV!$C10,TKB_HK2_Moi_Giang!$K:$K,ThongKe_GV!L$1,TKB_HK2_Moi_Giang!$L:$L,ThongKe_GV!L$2)>0,"X","") | ... AB10: =IF(COUNTIFS(TKB_HK2_Moi_Giang!$S:$S,ThongKe_GV!$C10,TKB_HK2_Moi_Giang!$K:$K,ThongKe_GV!AB$1,TKB_HK2_Moi_Giang!$L:$L,ThongKe_GV!AB$2)>0,"X","")
A11: =IF(MID(B11,4,1)="Q","Quản trị",IF(MID(B11,4,1)="T","Thiết kế",IF(MID(B11,4,1)="N","Ngoại ngữ",IF(MID(B11,4,1)="C","Công nghệ",IF(MID(B11,4,1)="Y","Y dược",IF(MID(B11,4,1)="V","Văn hóa","")))))) -> Ngoại ngữ | B11: CH-NN006 | C11: Quàng Thị Bảo Vy | D11: vy.quang@caodangvietmy.edu.vn | E11: =IF(COUNTIFS(TKB_HK2_Moi_Giang!$S:$S,ThongKe_GV!$C11,TKB_HK2_Moi_Giang!$K:$K,ThongKe_GV!E$1,TKB_HK2_Moi_Giang!$L:$L,ThongKe_GV!E$2)>0,"X","") | F11: =IF(COUNTIFS(TKB_HK2_Moi_Giang!$S:$S,ThongKe_GV!$C11,TKB_HK2_Moi_Giang!$K:$K,ThongKe_GV!F$1,TKB_HK2_Moi_Giang!$L:$L,ThongKe_GV!F$2)>0,"X","") -> X | G11: =IF(COUNTIFS(TKB_HK2_Moi_Giang!$S:$S,ThongKe_GV!$C11,TKB_HK2_Moi_Giang!$K:$K,ThongKe_GV!G$1,TKB_HK2_Moi_Giang!$L:$L,ThongKe_GV!G$2)>0,"X","") | H11: =IF(COUNTIFS(TKB_HK2_Moi_Giang!$S:$S,ThongKe_GV!$C11,TKB_HK2_Moi_Giang!$K:$K,ThongKe_GV!H$1,TKB_HK2_Moi_Giang!$L:$L,ThongKe_GV!H$2)>0,"X","") | I11: =IF(COUNTIFS(TKB_HK2_Moi_Giang!$S:$S,ThongKe_GV!$C11,TKB_HK2_Moi_Giang!$K:$K,ThongKe_GV!I$1,TKB_HK2_Moi_Giang!$L:$L,ThongKe_GV!I$2)>0,"X","") | J11: =IF(COUNTIFS(TKB_HK2_Moi_Giang!$S:$S,ThongKe_GV!$C11,TKB_HK2_Moi_Giang!$K:$K,ThongKe_GV!J$1,TKB_HK2_Moi_Giang!$L:$L,ThongKe_GV!J$2)>0,"X","") | K11: =IF(COUNTIFS(TKB_HK2_Moi_Giang!$S:$S,ThongKe_GV!$C11,TKB_HK2_Moi_Giang!$K:$K,ThongKe_GV!K$1,TKB_HK2_Moi_Giang!$L:$L,ThongKe_GV!K$2)>0,"X","") | L11: =IF(COUNTIFS(TKB_HK2_Moi_Giang!$S:$S,ThongKe_GV!$C11,TKB_HK2_Moi_Giang!$K:$K,ThongKe_GV!L$1,TKB_HK2_Moi_Giang!$L:$L,ThongKe_GV!L$2)>0,"X","") | ... AB11: =IF(COUNTIFS(TKB_HK2_Moi_Giang!$S:$S,ThongKe_GV!$C11,TKB_HK2_Moi_Giang!$K:$K,ThongKe_GV!AB$1,TKB_HK2_Moi_Giang!$L:$L,ThongKe_GV!AB$2)>0,"X","")
A12: =IF(MID(B12,4,1)="Q","Quản trị",IF(MID(B12,4,1)="T","Thiết kế",IF(MID(B12,4,1)="N","Ngoại ngữ",IF(MID(B12,4,1)="C","Công nghệ",IF(MID(B12,4,1)="Y","Y dược",IF(MID(B12,4,1)="V","Văn hóa","")))))) -> Ngoại ngữ | B12: TG-NN081 | C12: Lê Thị Ngọc Ánh | D12: anhxuan10d1@gmail.com | E12: =IF(COUNTIFS(TKB_HK2_Moi_Giang!$S:$S,ThongKe_GV!$C12,TKB_HK2_Moi_Giang!$K:$K,ThongKe_GV!E$1,TKB_HK2_Moi_Giang!$L:$L,ThongKe_GV!E$2)>0,"X","") | F12: =IF(COUNTIFS(TKB_HK2_Moi_Giang!$S:$S,ThongKe_GV!$C12,TKB_HK2_Moi_Giang!$K:$K,ThongKe_GV!F$1,TKB_HK2_Moi_Giang!$L:$L,ThongKe_GV!F$2)>0,"X","") | G12: =IF(COUNTIFS(TKB_HK2_Moi_Giang!$S:$S,ThongKe_GV!$C12,TKB_HK2_Moi_Giang!$K:$K,ThongKe_GV!G$1,TKB_HK2_Moi_Giang!$L:$L,ThongKe_GV!G$2)>0,"X","") | H12: =IF(COUNTIFS(TKB_HK2_Moi_Giang!$S:$S,ThongKe_GV!$C12,TKB_HK2_Moi_Giang!$K:$K,ThongKe_GV!H$1,TKB_HK2_Moi_Giang!$L:$L,ThongKe_GV!H$2)>0,"X","") | I12: =IF(COUNTIFS(TKB_HK2_Moi_Giang!$S:$S,ThongKe_GV!$C12,TKB_HK2_Moi_Giang!$K:$K,ThongKe_GV!I$1,TKB_HK2_Moi_Giang!$L:$L,ThongKe_GV!I$2)>0,"X","") | J12: =IF(COUNTIFS(TKB_HK2_Moi_Giang!$S:$S,ThongKe_GV!$C12,TKB_HK2_Moi_Giang!$K:$K,ThongKe_GV!J$1,TKB_HK2_Moi_Giang!$L:$L,ThongKe_GV!J$2)>0,"X","") | K12: =IF(COUNTIFS(TKB_HK2_Moi_Giang!$S:$S,ThongKe_GV!$C12,TKB_HK2_Moi_Giang!$K:$K,ThongKe_GV!K$1,TKB_HK2_Moi_Giang!$L:$L,ThongKe_GV!K$2)>0,"X","") | L12: =IF(COUNTIFS(TKB_HK2_Moi_Giang!$S:$S,ThongKe_GV!$C12,TKB_HK2_Moi_Giang!$K:$K,ThongKe_GV!L$1,TKB_HK2_Moi_Giang!$L:$L,ThongKe_GV!L$2)>0,"X","") | ... AB12: =IF(COUNTIFS(TKB_HK2_Moi_Giang!$S:$S,ThongKe_GV!$C12,TKB_HK2_Moi_Giang!$K:$K,ThongKe_GV!AB$1,TKB_HK2_Moi_Giang!$L:$L,ThongKe_GV!AB$2)>0,"X","")
A13: =IF(MID(B13,4,1)="Q","Quản trị",IF(MID(B13,4,1)="T","Thiết kế",IF(MID(B13,4,1)="N","Ngoại ngữ",IF(MID(B13,4,1)="C","Công nghệ",IF(MID(B13,4,1)="Y","Y dược",IF(MID(B13,4,1)="V","Văn hóa","")))))) -> Quản trị | B13: TG-QT104 | C13: Vũ Nhật Tân | D13: vn.tan@hutech.edu.vn | E13: =IF(COUNTIFS(TKB_HK2_Moi_Giang!$S:$S,ThongKe_GV!$C13,TKB_HK2_Moi_Giang!$K:$K,ThongKe_GV!E$1,TKB_HK2_Moi_Giang!$L:$L,ThongKe_GV!E$2)>0,"X","") | F13: =IF(COUNTIFS(TKB_HK2_Moi_Giang!$S:$S,ThongKe_GV!$C13,TKB_HK2_Moi_Giang!$K:$K,ThongKe_GV!F$1,TKB_HK2_Moi_Giang!$L:$L,ThongKe_GV!F$2)>0,"X","") | G13: =IF(COUNTIFS(TKB_HK2_Moi_Giang!$S:$S,ThongKe_GV!$C13,TKB_HK2_Moi_Giang!$K:$K,ThongKe_GV!G$1,TKB_HK2_Moi_Giang!$L:$L,ThongKe_GV!G$2)>0,"X","") | H13: =IF(COUNTIFS(TKB_HK2_Moi_Giang!$S:$S,ThongKe_GV!$C13,TKB_HK2_Moi_Giang!$K:$K,ThongKe_GV!H$1,TKB_HK2_Moi_Giang!$L:$L,ThongKe_GV!H$2)>0,"X","") | I13: =IF(COUNTIFS(TKB_HK2_Moi_Giang!$S:$S,ThongKe_GV!$C13,TKB_HK2_Moi_Giang!$K:$K,ThongKe_GV!I$1,TKB_HK2_Moi_Giang!$L:$L,ThongKe_GV!I$2)>0,"X","") | J13: =IF(COUNTIFS(TKB_HK2_Moi_Giang!$S:$S,ThongKe_GV!$C13,TKB_HK2_Moi_Giang!$K:$K,ThongKe_GV!J$1,TKB_HK2_Moi_Giang!$L:$L,ThongKe_GV!J$2)>0,"X","") | K13: =IF(COUNTIFS(TKB_HK2_Moi_Giang!$S:$S,ThongKe_GV!$C13,TKB_HK2_Moi_Giang!$K:$K,ThongKe_GV!K$1,TKB_HK2_Moi_Giang!$L:$L,ThongKe_GV!K$2)>0,"X","") | L13: =IF(COUNTIFS(TKB_HK2_Moi_Giang!$S:$S,ThongKe_GV!$C13,TKB_HK2_Moi_Giang!$K:$K,ThongKe_GV!L$1,TKB_HK2_Moi_Giang!$L:$L,ThongKe_GV!L$2)>0,"X","") | ... AB13: =IF(COUNTIFS(TKB_HK2_Moi_Giang!$S:$S,ThongKe_GV!$C13,TKB_HK2_Moi_Giang!$K:$K,ThongKe_GV!AB$1,TKB_HK2_Moi_Giang!$L:$L,ThongKe_GV!AB$2)>0,"X","")
B14: TG-TA002 | C14: Nguyễn Tuấn Anh | D14: nguyentuananh03081986@gmail.com | E14: =IF(COUNTIFS(TKB_HK2_Moi_Giang!$S:$S,ThongKe_GV!$C14,TKB_HK2_Moi_Giang!$K:$K,ThongKe_GV!E$1,TKB_HK2_Moi_Giang!$L:$L,ThongKe_GV!E$2)>0,"X","") | F14: =IF(COUNTIFS(TKB_HK2_Moi_Giang!$S:$S,ThongKe_GV!$C14,TKB_HK2_Moi_Giang!$K:$K,ThongKe_GV!F$1,TKB_HK2_Moi_Giang!$L:$L,ThongKe_GV!F$2)>0,"X","") | G14: =IF(COUNTIFS(TKB_HK2_Moi_Giang!$S:$S,ThongKe_GV!$C14,TKB_HK2_Moi_Giang!$K:$K,ThongKe_GV!G$1,TKB_HK2_Moi_Giang!$L:$L,ThongKe_GV!G$2)>0,"X","") | H14: =IF(COUNTIFS(TKB_HK2_Moi_Giang!$S:$S,ThongKe_GV!$C14,TKB_HK2_Moi_Giang!$K:$K,ThongKe_GV!H$1,TKB_HK2_Moi_Giang!$L:$L,ThongKe_GV!H$2)>0,"X","") | I14: =IF(COUNTIFS(TKB_HK2_Moi_Giang!$S:$S,ThongKe_GV!$C14,TKB_HK2_Moi_Giang!$K:$K,ThongKe_GV!I$1,TKB_HK2_Moi_Giang!$L:$L,ThongKe_GV!I$2)>0,"X","") | J14: =IF(COUNTIFS(TKB_HK2_Moi_Giang!$S:$S,ThongKe_GV!$C14,TKB_HK2_Moi_Giang!$K:$K,ThongKe_GV!J$1,TKB_HK2_Moi_Giang!$L:$L,ThongKe_GV!J$2)>0,"X","") | K14: =IF(COUNTIFS(TKB_HK2_Moi_Giang!$S:$S,ThongKe_GV!$C14,TKB_HK2_Moi_Giang!$K:$K,ThongKe_GV!K$1,TKB_HK2_Moi_Giang!$L:$L,ThongKe_GV!K$2)>0,"X","") | L14: =IF(COUNTIFS(TKB_HK2_Moi_Giang!$S:$S,ThongKe_GV!$C14,TKB_HK2_Moi_Giang!$K:$K,ThongKe_GV!L$1,TKB_HK2_Moi_Giang!$L:$L,ThongKe_GV!L$2)>0,"X","") | ... AB14: =IF(COUNTIFS(TKB_HK2_Moi_Giang!$S:$S,ThongKe_GV!$C14,TKB_HK2_Moi_Giang!$K:$K,ThongKe_GV!AB$1,TKB_HK2_Moi_Giang!$L:$L,ThongKe_GV!AB$2)>0,"X","")
A15: =IF(MID(B15,4,1)="Q","Quản trị",IF(MID(B15,4,1)="T","Thiết kế",IF(MID(B15,4,1)="N","Ngoại ngữ",IF(MID(B15,4,1)="C","Công nghệ",IF(MID(B15,4,1)="Y","Y dược",IF(MID(B15,4,1)="V","Văn hóa","")))))) -> Thiết kế | B15: TG-TK39 | C15: Nguyễn Huỳnh | D15: ng.huynh95@gmail.com | E15: =IF(COUNTIFS(TKB_HK2_Moi_Giang!$S:$S,ThongKe_GV!$C15,TKB_HK2_Moi_Giang!$K:$K,ThongKe_GV!E$1,TKB_HK2_Moi_Giang!$L:$L,ThongKe_GV!E$2)>0,"X","") | F15: =IF(COUNTIFS(TKB_HK2_Moi_Giang!$S:$S,ThongKe_GV!$C15,TKB_HK2_Moi_Giang!$K:$K,ThongKe_GV!F$1,TKB_HK2_Moi_Giang!$L:$L,ThongKe_GV!F$2)>0,"X","") | G15: =IF(COUNTIFS(TKB_HK2_Moi_Giang!$S:$S,ThongKe_GV!$C15,TKB_HK2_Moi_Giang!$K:$K,ThongKe_GV!G$1,TKB_HK2_Moi_Giang!$L:$L,ThongKe_GV!G$2)>0,"X","") | H15: =IF(COUNTIFS(TKB_HK2_Moi_Giang!$S:$S,ThongKe_GV!$C15,TKB_HK2_Moi_Giang!$K:$K,ThongKe_GV!H$1,TKB_HK2_Moi_Giang!$L:$L,ThongKe_GV!H$2)>0,"X","") | I15: =IF(COUNTIFS(TKB_HK2_Moi_Giang!$S:$S,ThongKe_GV!$C15,TKB_HK2_Moi_Giang!$K:$K,ThongKe_GV!I$1,TKB_HK2_Moi_Giang!$L:$L,ThongKe_GV!I$2)>0,"X","") | J15: =IF(COUNTIFS(TKB_HK2_Moi_Giang!$S:$S,ThongKe_GV!$C15,TKB_HK2_Moi_Giang!$K:$K,ThongKe_GV!J$1,TKB_HK2_Moi_Giang!$L:$L,ThongKe_GV!J$2)>0,"X","") | K15: =IF(COUNTIFS(TKB_HK2_Moi_Giang!$S:$S,ThongKe_GV!$C15,TKB_HK2_Moi_Giang!$K:$K,ThongKe_GV!K$1,TKB_HK2_Moi_Giang!$L:$L,ThongKe_GV!K$2)>0,"X","") | L15: =IF(COUNTIFS(TKB_HK2_Moi_Giang!$S:$S,ThongKe_GV!$C15,TKB_HK2_Moi_Giang!$K:$K,ThongKe_GV!L$1,TKB_HK2_Moi_Giang!$L:$L,ThongKe_GV!L$2)>0,"X","") | ... AB15: =IF(COUNTIFS(TKB_HK2_Moi_Giang!$S:$S,ThongKe_GV!$C15,TKB_HK2_Moi_Giang!$K:$K,ThongKe_GV!AB$1,TKB_HK2_Moi_Giang!$L:$L,ThongKe_GV!AB$2)>0,"X","")
A16: =IF(MID(B16,4,1)="Q","Quản trị",IF(MID(B16,4,1)="T","Thiết kế",IF(MID(B16,4,1)="N","Ngoại ngữ",IF(MID(B16,4,1)="C","Công nghệ",IF(MID(B16,4,1)="Y","Y dược",IF(MID(B16,4,1)="V","Văn hóa","")))))) -> Quản trị | B16: TG-QT098 | C16: Nguyễn Ngọc Sĩ Đan | D16: dan.nguyenngocsi@stu.edu.vn | E16: =IF(COUNTIFS(TKB_HK2_Moi_Giang!$S:$S,ThongKe_GV!$C16,TKB_HK2_Moi_Giang!$K:$K,ThongKe_GV!E$1,TKB_HK2_Moi_Giang!$L:$L,ThongKe_GV!E$2)>0,"X","") | F16: =IF(COUNTIFS(TKB_HK2_Moi_Giang!$S:$S,ThongKe_GV!$C16,TKB_HK2_Moi_Giang!$K:$K,ThongKe_GV!F$1,TKB_HK2_Moi_Giang!$L:$L,ThongKe_GV!F$2)>0,"X","") | G16: =IF(COUNTIFS(TKB_HK2_Moi_Giang!$S:$S,ThongKe_GV!$C16,TKB_HK2_Moi_Giang!$K:$K,ThongKe_GV!G$1,TKB_HK2_Moi_Giang!$L:$L,ThongKe_GV!G$2)>0,"X","") | H16: =IF(COUNTIFS(TKB_HK2_Moi_Giang!$S:$S,ThongKe_GV!$C16,TKB_HK2_Moi_Giang!$K:$K,ThongKe_GV!H$1,TKB_HK2_Moi_Giang!$L:$L,ThongKe_GV!H$2)>0,"X","") | I16: =IF(COUNTIFS(TKB_HK2_Moi_Giang!$S:$S,ThongKe_GV!$C16,TKB_HK2_Moi_Giang!$K:$K,ThongKe_GV!I$1,TKB_HK2_Moi_Giang!$L:$L,ThongKe_GV!I$2)>0,"X","") | J16: =IF(COUNTIFS(TKB_HK2_Moi_Giang!$S:$S,ThongKe_GV!$C16,TKB_HK2_Moi_Giang!$K:$K,ThongKe_GV!J$1,TKB_HK2_Moi_Giang!$L:$L,ThongKe_GV!J$2)>0,"X","") -> X | K16: =IF(COUNTIFS(TKB_HK2_Moi_Giang!$S:$S,ThongKe_GV!$C16,TKB_HK2_Moi_Giang!$K:$K,ThongKe_GV!K$1,TKB_HK2_Moi_Giang!$L:$L,ThongKe_GV!K$2)>0,"X","") | L16: =IF(COUNTIFS(TKB_HK2_Moi_Giang!$S:$S,ThongKe_GV!$C16,TKB_HK2_Moi_Giang!$K:$K,ThongKe_GV!L$1,TKB_HK2_Moi_Giang!$L:$L,ThongKe_GV!L$2)>0,"X","") | ... AB16: =IF(COUNTIFS(TKB_HK2_Moi_Giang!$S:$S,ThongKe_GV!$C16,TKB_HK2_Moi_Giang!$K:$K,ThongKe_GV!AB$1,TKB_HK2_Moi_Giang!$L:$L,ThongKe_GV!AB$2)>0,"X","")
A17: =IF(MID(B17,4,1)="Q","Quản trị",IF(MID(B17,4,1)="T","Thiết kế",IF(MID(B17,4,1)="N","Ngoại ngữ",IF(MID(B17,4,1)="C","Công nghệ",IF(MID(B17,4,1)="Y","Y dược",IF(MID(B17,4,1)="V","Văn hóa","")))))) | B17: TG-BTEC060 | C17: Nguyễn Thị Thanh Nga | D17: nganguyendesigner@gmail.com | E17: =IF(COUNTIFS(TKB_HK2_Moi_Giang!$S:$S,ThongKe_GV!$C17,TKB_HK2_Moi_Giang!$K:$K,ThongKe_GV!E$1,TKB_HK2_Moi_Giang!$L:$L,ThongKe_GV!E$2)>0,"X","") | F17: =IF(COUNTIFS(TKB_HK2_Moi_Giang!$S:$S,ThongKe_GV!$C17,TKB_HK2_Moi_Giang!$K:$K,ThongKe_GV!F$1,TKB_HK2_Moi_Giang!$L:$L,ThongKe_GV!F$2)>0,"X","") | G17: =IF(COUNTIFS(TKB_HK2_Moi_Giang!$S:$S,ThongKe_GV!$C17,TKB_HK2_Moi_Giang!$K:$K,ThongKe_GV!G$1,TKB_HK2_Moi_Giang!$L:$L,ThongKe_GV!G$2)>0,"X","") | H17: =IF(COUNTIFS(TKB_HK2_Moi_Giang!$S:$S,ThongKe_GV!$C17,TKB_HK2_Moi_Giang!$K:$K,ThongKe_GV!H$1,TKB_HK2_Moi_Giang!$L:$L,ThongKe_GV!H$2)>0,"X","") | I17: =IF(COUNTIFS(TKB_HK2_Moi_Giang!$S:$S,ThongKe_GV!$C17,TKB_HK2_Moi_Giang!$K:$K,ThongKe_GV!I$1,TKB_HK2_Moi_Giang!$L:$L,ThongKe_GV!I$2)>0,"X","") | J17: =IF(COUNTIFS(TKB_HK2_Moi_Giang!$S:$S,ThongKe_GV!$C17,TKB_HK2_Moi_Giang!$K:$K,ThongKe_GV!J$1,TKB_HK2_Moi_Giang!$L:$L,ThongKe_GV!J$2)>0,"X","") | K17: =IF(COUNTIFS(TKB_HK2_Moi_Giang!$S:$S,ThongKe_GV!$C17,TKB_HK2_Moi_Giang!$K:$K,ThongKe_GV!K$1,TKB_HK2_Moi_Giang!$L:$L,ThongKe_GV!K$2)>0,"X","") | L17: =IF(COUNTIFS(TKB_HK2_Moi_Giang!$S:$S,ThongKe_GV!$C17,TKB_HK2_Moi_Giang!$K:$K,ThongKe_GV!L$1,TKB_HK2_Moi_Giang!$L:$L,ThongKe_GV!L$2)>0,"X","") | ... AB17: =IF(COUNTIFS(TKB_HK2_Moi_Giang!$S:$S,ThongKe_GV!$C17,TKB_HK2_Moi_Giang!$K:$K,ThongKe_GV!AB$1,TKB_HK2_Moi_Giang!$L:$L,ThongKe_GV!AB$2)>0,"X","")
A18: =IF(MID(B18,4,1)="Q","Quản trị",IF(MID(B18,4,1)="T","Thiết kế",IF(MID(B18,4,1)="N","Ngoại ngữ",IF(MID(B18,4,1)="C","Công nghệ",IF(MID(B18,4,1)="Y","Y dược",IF(MID(B18,4,1)="V","Văn hóa","")))))) -> Văn hóa | B18: TG-VH005 | C18: Đỗ Đinh Linh Vũ | D18: linhvudodhsp@gmail.com | E18: =IF(COUNTIFS(TKB_HK2_Moi_Giang!$S:$S,ThongKe_GV!$C18,TKB_HK2_Moi_Giang!$K:$K,ThongKe_GV!E$1,TKB_HK2_Moi_Giang!$L:$L,ThongKe_GV!E$2)>0,"X","") | F18: =IF(COUNTIFS(TKB_HK2_Moi_Giang!$S:$S,ThongKe_GV!$C18,TKB_HK2_Moi_Giang!$K:$K,ThongKe_GV!F$1,TKB_HK2_Moi_Giang!$L:$L,ThongKe_GV!F$2)>0,"X","") | G18: =IF(COUNTIFS(TKB_HK2_Moi_Giang!$S:$S,ThongKe_GV!$C18,TKB_HK2_Moi_Giang!$K:$K,ThongKe_GV!G$1,TKB_HK2_Moi_Giang!$L:$L,ThongKe_GV!G$2)>0,"X","") | H18: =IF(COUNTIFS(TKB_HK2_Moi_Giang!$S:$S,ThongKe_GV!$C18,TKB_HK2_Moi_Giang!$K:$K,ThongKe_GV!H$1,TKB_HK2_Moi_Giang!$L:$L,ThongKe_GV!H$2)>0,"X","") | I18: =IF(COUNTIFS(TKB_HK2_Moi_Giang!$S:$S,ThongKe_GV!$C18,TKB_HK2_Moi_Giang!$K:$K,ThongKe_GV!I$1,TKB_HK2_Moi_Giang!$L:$L,ThongKe_GV!I$2)>0,"X","") | J18: =IF(COUNTIFS(TKB_HK2_Moi_Giang!$S:$S,ThongKe_GV!$C18,TKB_HK2_Moi_Giang!$K:$K,ThongKe_GV!J$1,TKB_HK2_Moi_Giang!$L:$L,ThongKe_GV!J$2)>0,"X","") | K18: =IF(COUNTIFS(TKB_HK2_Moi_Giang!$S:$S,ThongKe_GV!$C18,TKB_HK2_Moi_Giang!$K:$K,ThongKe_GV!K$1,TKB_HK2_Moi_Giang!$L:$L,ThongKe_GV!K$2)>0,"X","") | L18: =IF(COUNTIFS(TKB_HK2_Moi_Giang!$S:$S,ThongKe_GV!$C18,TKB_HK2_Moi_Giang!$K:$K,ThongKe_GV!L$1,TKB_HK2_Moi_Giang!$L:$L,ThongKe_GV!L$2)>0,"X","") | ... AB18: =IF(COUNTIFS(TKB_HK2_Moi_Giang!$S:$S,ThongKe_GV!$C18,TKB_HK2_Moi_Giang!$K:$K,ThongKe_GV!AB$1,TKB_HK2_Moi_Giang!$L:$L,ThongKe_GV!AB$2)>0,"X","")
A19: =IF(MID(B19,4,1)="Q","Quản trị",IF(MID(B19,4,1)="T","Thiết kế",IF(MID(B19,4,1)="N","Ngoại ngữ",IF(MID(B19,4,1)="C","Công nghệ",IF(MID(B19,4,1)="Y","Y dược",IF(MID(B19,4,1)="V","Văn hóa","")))))) -> Ngoại ngữ | B19: TG-NN087 | C19: Trần Thị Thanh Thanh | D19: thanhthanh6495@gmail.com | E19: =IF(COUNTIFS(TKB_HK2_Moi_Giang!$S:$S,ThongKe_GV!$C19,TKB_HK2_Moi_Giang!$K:$K,ThongKe_GV!E$1,TKB_HK2_Moi_Giang!$L:$L,ThongKe_GV!E$2)>0,"X","") | F19: =IF(COUNTIFS(TKB_HK2_Moi_Giang!$S:$S,ThongKe_GV!$C19,TKB_HK2_Moi_Giang!$K:$K,ThongKe_GV!F$1,TKB_HK2_Moi_Giang!$L:$L,ThongKe_GV!F$2)>0,"X","") | G19: =IF(COUNTIFS(TKB_HK2_Moi_Giang!$S:$S,ThongKe_GV!$C19,TKB_HK2_Moi_Giang!$K:$K,ThongKe_GV!G$1,TKB_HK2_Moi_Giang!$L:$L,ThongKe_GV!G$2)>0,"X","") | H19: =IF(COUNTIFS(TKB_HK2_Moi_Giang!$S:$S,ThongKe_GV!$C19,TKB_HK2_Moi_Giang!$K:$K,ThongKe_GV!H$1,TKB_HK2_Moi_Giang!$L:$L,ThongKe_GV!H$2)>0,"X","") | I19: =IF(COUNTIFS(TKB_HK2_Moi_Giang!$S:$S,ThongKe_GV!$C19,TKB_HK2_Moi_Giang!$K:$K,ThongKe_GV!I$1,TKB_HK2_Moi_Giang!$L:$L,ThongKe_GV!I$2)>0,"X","") | J19: =IF(COUNTIFS(TKB_HK2_Moi_Giang!$S:$S,ThongKe_GV!$C19,TKB_HK2_Moi_Giang!$K:$K,ThongKe_GV!J$1,TKB_HK2_Moi_Giang!$L:$L,ThongKe_GV!J$2)>0,"X","") | K19: =IF(COUNTIFS(TKB_HK2_Moi_Giang!$S:$S,ThongKe_GV!$C19,TKB_HK2_Moi_Giang!$K:$K,ThongKe_GV!K$1,TKB_HK2_Moi_Giang!$L:$L,ThongKe_GV!K$2)>0,"X","") | L19: =IF(COUNTIFS(TKB_HK2_Moi_Giang!$S:$S,ThongKe_GV!$C19,TKB_HK2_Moi_Giang!$K:$K,ThongKe_GV!L$1,TKB_HK2_Moi_Giang!$L:$L,ThongKe_GV!L$2)>0,"X","") | ... AB19: =IF(COUNTIFS(TKB_HK2_Moi_Giang!$S:$S,ThongKe_GV!$C19,TKB_HK2_Moi_Giang!$K:$K,ThongKe_GV!AB$1,TKB_HK2_Moi_Giang!$L:$L,ThongKe_GV!AB$2)>0,"X","")
A20: =IF(MID(B20,4,1)="Q","Quản trị",IF(MID(B20,4,1)="T","Thiết kế",IF(MID(B20,4,1)="N","Ngoại ngữ",IF(MID(B20,4,1)="C","Công nghệ",IF(MID(B20,4,1)="Y","Y dược",IF(MID(B20,4,1)="V","Văn hóa","")))))) -> Ngoại ngữ | B20: TG-NN49 | C20: Nguyễn Khánh Lĩnh | D20: khanhlinhmicvang@gmail.com | E20: =IF(COUNTIFS(TKB_HK2_Moi_Giang!$S:$S,ThongKe_GV!$C20,TKB_HK2_Moi_Giang!$K:$K,ThongKe_GV!E$1,TKB_HK2_Moi_Giang!$L:$L,ThongKe_GV!E$2)>0,"X","") | F20: =IF(COUNTIFS(TKB_HK2_Moi_Giang!$S:$S,ThongKe_GV!$C20,TKB_HK2_Moi_Giang!$K:$K,ThongKe_GV!F$1,TKB_HK2_Moi_Giang!$L:$L,ThongKe_GV!F$2)>0,"X","") | G20: =IF(COUNTIFS(TKB_HK2_Moi_Giang!$S:$S,ThongKe_GV!$C20,TKB_HK2_Moi_Giang!$K:$K,ThongKe_GV!G$1,TKB_HK2_Moi_Giang!$L:$L,ThongKe_GV!G$2)>0,"X","") | H20: =IF(COUNTIFS(TKB_HK2_Moi_Giang!$S:$S,ThongKe_GV!$C20,TKB_HK2_Moi_Giang!$K:$K,ThongKe_GV!H$1,TKB_HK2_Moi_Giang!$L:$L,ThongKe_GV!H$2)>0,"X","") | I20: =IF(COUNTIFS(TKB_HK2_Moi_Giang!$S:$S,ThongKe_GV!$C20,TKB_HK2_Moi_Giang!$K:$K,ThongKe_GV!I$1,TKB_HK2_Moi_Giang!$L:$L,ThongKe_GV!I$2)>0,"X","") | J20: =IF(COUNTIFS(TKB_HK2_Moi_Giang!$S:$S,ThongKe_GV!$C20,TKB_HK2_Moi_Giang!$K:$K,ThongKe_GV!J$1,TKB_HK2_Moi_Giang!$L:$L,ThongKe_GV!J$2)>0,"X","") | K20: =IF(COUNTIFS(TKB_HK2_Moi_Giang!$S:$S,ThongKe_GV!$C20,TKB_HK2_Moi_Giang!$K:$K,ThongKe_GV!K$1,TKB_HK2_Moi_Giang!$L:$L,ThongKe_GV!K$2)>0,"X","") | L20: =IF(COUNTIFS(TKB_HK2_Moi_Giang!$S:$S,ThongKe_GV!$C20,TKB_HK2_Moi_Giang!$K:$K,ThongKe_GV!L$1,TKB_HK2_Moi_Giang!$L:$L,ThongKe_GV!L$2)>0,"X","") | ... AB20: =IF(COUNTIFS(TKB_HK2_Moi_Giang!$S:$S,ThongKe_GV!$C20,TKB_HK2_Moi_Giang!$K:$K,ThongKe_GV!AB$1,TKB_HK2_Moi_Giang!$L:$L,ThongKe_GV!AB$2)>0,"X","")
A21: =IF(MID(B21,4,1)="Q","Quản trị",IF(MID(B21,4,1)="T","Thiết kế",IF(MID(B21,4,1)="N","Ngoại ngữ",IF(MID(B21,4,1)="C","Công nghệ",IF(MID(B21,4,1)="Y","Y dược",IF(MID(B21,4,1)="V","Văn hóa","")))))) -> Quản trị | B21: TG-QT0100 | C21: Trần Mỹ Ngọc | D21: tranngocpt1512@gmail.com | E21: =IF(COUNTIFS(TKB_HK2_Moi_Giang!$S:$S,ThongKe_GV!$C21,TKB_HK2_Moi_Giang!$K:$K,ThongKe_GV!E$1,TKB_HK2_Moi_Giang!$L:$L,ThongKe_GV!E$2)>0,"X","") | F21: =IF(COUNTIFS(TKB_HK2_Moi_Giang!$S:$S,ThongKe_GV!$C21,TKB_HK2_Moi_Giang!$K:$K,ThongKe_GV!F$1,TKB_HK2_Moi_Giang!$L:$L,ThongKe_GV!F$2)>0,"X","") | G21: =IF(COUNTIFS(TKB_HK2_Moi_Giang!$S:$S,ThongKe_GV!$C21,TKB_HK2_Moi_Giang!$K:$K,ThongKe_GV!G$1,TKB_HK2_Moi_Giang!$L:$L,ThongKe_GV!G$2)>0,"X","") | H21: =IF(COUNTIFS(TKB_HK2_Moi_Giang!$S:$S,ThongKe_GV!$C21,TKB_HK2_Moi_Giang!$K:$K,ThongKe_GV!H$1,TKB_HK2_Moi_Giang!$L:$L,ThongKe_GV!H$2)>0,"X","") | I21: =IF(COUNTIFS(TKB_HK2_Moi_Giang!$S:$S,ThongKe_GV!$C21,TKB_HK2_Moi_Giang!$K:$K,ThongKe_GV!I$1,TKB_HK2_Moi_Giang!$L:$L,ThongKe_GV!I$2)>0,"X","") | J21: =IF(COUNTIFS(TKB_HK2_Moi_Giang!$S:$S,ThongKe_GV!$C21,TKB_HK2_Moi_Giang!$K:$K,ThongKe_GV!J$1,TKB_HK2_Moi_Giang!$L:$L,ThongKe_GV!J$2)>0,"X","") | K21: =IF(COUNTIFS(TKB_HK2_Moi_Giang!$S:$S,ThongKe_GV!$C21,TKB_HK2_Moi_Giang!$K:$K,ThongKe_GV!K$1,TKB_HK2_Moi_Giang!$L:$L,ThongKe_GV!K$2)>0,"X","") | L21: =IF(COUNTIFS(TKB_HK2_Moi_Giang!$S:$S,ThongKe_GV!$C21,TKB_HK2_Moi_Giang!$K:$K,ThongKe_GV!L$1,TKB_HK2_Moi_Giang!$L:$L,ThongKe_GV!L$2)>0,"X","") | ... AB21: =IF(COUNTIFS(TKB_HK2_Moi_Giang!$S:$S,ThongKe_GV!$C21,TKB_HK2_Moi_Giang!$K:$K,ThongKe_GV!AB$1,TKB_HK2_Moi_Giang!$L:$L,ThongKe_GV!AB$2)>0,"X","")
A22: =IF(MID(B22,4,1)="Q","Quản trị",IF(MID(B22,4,1)="T","Thiết kế",IF(MID(B22,4,1)="N","Ngoại ngữ",IF(MID(B22,4,1)="C","Công nghệ",IF(MID(B22,4,1)="Y","Y dược",IF(MID(B22,4,1)="V","Văn hóa","")))))) -> Công nghệ | B22: TG-CNTT019 | C22: Châu Trần Trúc Ly | D22: chautrantrucly@gmail.com | E22: =IF(COUNTIFS(TKB_HK2_Moi_Giang!$S:$S,ThongKe_GV!$C22,TKB_HK2_Moi_Giang!$K:$K,ThongKe_GV!E$1,TKB_HK2_Moi_Giang!$L:$L,ThongKe_GV!E$2)>0,"X","") | F22: =IF(COUNTIFS(TKB_HK2_Moi_Giang!$S:$S,ThongKe_GV!$C22,TKB_HK2_Moi_Giang!$K:$K,ThongKe_GV!F$1,TKB_HK2_Moi_Giang!$L:$L,ThongKe_GV!F$2)>0,"X","") | G22: =IF(COUNTIFS(TKB_HK2_Moi_Giang!$S:$S,ThongKe_GV!$C22,TKB_HK2_Moi_Giang!$K:$K,ThongKe_GV!G$1,TKB_HK2_Moi_Giang!$L:$L,ThongKe_GV!G$2)>0,"X","") | H22: =IF(COUNTIFS(TKB_HK2_Moi_Giang!$S:$S,ThongKe_GV!$C22,TKB_HK2_Moi_Giang!$K:$K,ThongKe_GV!H$1,TKB_HK2_Moi_Giang!$L:$L,ThongKe_GV!H$2)>0,"X","") | I22: =IF(COUNTIFS(TKB_HK2_Moi_Giang!$S:$S,ThongKe_GV!$C22,TKB_HK2_Moi_Giang!$K:$K,ThongKe_GV!I$1,TKB_HK2_Moi_Giang!$L:$L,ThongKe_GV!I$2)>0,"X","") | J22: =IF(COUNTIFS(TKB_HK2_Moi_Giang!$S:$S,ThongKe_GV!$C22,TKB_HK2_Moi_Giang!$K:$K,ThongKe_GV!J$1,TKB_HK2_Moi_Giang!$L:$L,ThongKe_GV!J$2)>0,"X","") | K22: =IF(COUNTIFS(TKB_HK2_Moi_Giang!$S:$S,ThongKe_GV!$C22,TKB_HK2_Moi_Giang!$K:$K,ThongKe_GV!K$1,TKB_HK2_Moi_Giang!$L:$L,ThongKe_GV!K$2)>0,"X","") | L22: =IF(COUNTIFS(TKB_HK2_Moi_Giang!$S:$S,ThongKe_GV!$C22,TKB_HK2_Moi_Giang!$K:$K,ThongKe_GV!L$1,TKB_HK2_Moi_Giang!$L:$L,ThongKe_GV!L$2)>0,"X","") | ... AB22: =IF(COUNTIFS(TKB_HK2_Moi_Giang!$S:$S,ThongKe_GV!$C22,TKB_HK2_Moi_Giang!$K:$K,ThongKe_GV!AB$1,TKB_HK2_Moi_Giang!$L:$L,ThongKe_GV!AB$2)>0,"X","")
A23: =IF(MID(B23,4,1)="Q","Quản trị",IF(MID(B23,4,1)="T","Thiết kế",IF(MID(B23,4,1)="N","Ngoại ngữ",IF(MID(B23,4,1)="C","Công nghệ",IF(MID(B23,4,1)="Y","Y dược",IF(MID(B23,4,1)="V","Văn hóa","")))))) -> Quản trị | B23: TG-QT060 | C23: Bùi Thị Hồng Thắm | D23: tham.bui@caodangvietmy.edu.vn | E23: =IF(COUNTIFS(TKB_HK2_Moi_Giang!$S:$S,ThongKe_GV!$C23,TKB_HK2_Moi_Giang!$K:$K,ThongKe_GV!E$1,TKB_HK2_Moi_Giang!$L:$L,ThongKe_GV!E$2)>0,"X","") | F23: =IF(COUNTIFS(TKB_HK2_Moi_Giang!$S:$S,ThongKe_GV!$C23,TKB_HK2_Moi_Giang!$K:$K,ThongKe_GV!F$1,TKB_HK2_Moi_Giang!$L:$L,ThongKe_GV!F$2)>0,"X","") | G23: =IF(COUNTIFS(TKB_HK2_Moi_Giang!$S:$S,ThongKe_GV!$C23,TKB_HK2_Moi_Giang!$K:$K,ThongKe_GV!G$1,TKB_HK2_Moi_Giang!$L:$L,ThongKe_GV!G$2)>0,"X","") | H23: =IF(COUNTIFS(TKB_HK2_Moi_Giang!$S:$S,ThongKe_GV!$C23,TKB_HK2_Moi_Giang!$K:$K,ThongKe_GV!H$1,TKB_HK2_Moi_Giang!$L:$L,ThongKe_GV!H$2)>0,"X","") | I23: =IF(COUNTIFS(TKB_HK2_Moi_Giang!$S:$S,ThongKe_GV!$C23,TKB_HK2_Moi_Giang!$K:$K,ThongKe_GV!I$1,TKB_HK2_Moi_Giang!$L:$L,ThongKe_GV!I$2)>0,"X","") -> X | J23: =IF(COUNTIFS(TKB_HK2_Moi_Giang!$S:$S,ThongKe_GV!$C23,TKB_HK2_Moi_Giang!$K:$K,ThongKe_GV!J$1,TKB_HK2_Moi_Giang!$L:$L,ThongKe_GV!J$2)>0,"X","") | K23: =IF(COUNTIFS(TKB_HK2_Moi_Giang!$S:$S,ThongKe_GV!$C23,TKB_HK2_Moi_Giang!$K:$K,ThongKe_GV!K$1,TKB_HK2_Moi_Giang!$L:$L,ThongKe_GV!K$2)>0,"X","") | L23: =IF(COUNTIFS(TKB_HK2_Moi_Giang!$S:$S,ThongKe_GV!$C23,TKB_HK2_Moi_Giang!$K:$K,ThongKe_GV!L$1,TKB_HK2_Moi_Giang!$L:$L,ThongKe_GV!L$2)>0,"X","") | ... AB23: =IF(COUNTIFS(TKB_HK2_Moi_Giang!$S:$S,ThongKe_GV!$C23,TKB_HK2_Moi_Giang!$K:$K,ThongKe_GV!AB$1,TKB_HK2_Moi_Giang!$L:$L,ThongKe_GV!AB$2)>0,"X","")
A24: =IF(MID(B24,4,1)="Q","Quản trị",IF(MID(B24,4,1)="T","Thiết kế",IF(MID(B24,4,1)="N","Ngoại ngữ",IF(MID(B24,4,1)="C","Công nghệ",IF(MID(B24,4,1)="Y","Y dược",IF(MID(B24,4,1)="V","Văn hóa","")))))) -> Thiết kế | B24: TG-TK005 | C24: Bùi Thị Tuyết Hương | D24: ktk.thoitrang25.hcm@caodangvietmy.edu.vn | E24: =IF(COUNTIFS(TKB_HK2_Moi_Giang!$S:$S,ThongKe_GV!$C24,TKB_HK2_Moi_Giang!$K:$K,ThongKe_GV!E$1,TKB_HK2_Moi_Giang!$L:$L,ThongKe_GV!E$2)>0,"X","") | F24: =IF(COUNTIFS(TKB_HK2_Moi_Giang!$S:$S,ThongKe_GV!$C24,TKB_HK2_Moi_Giang!$K:$K,ThongKe_GV!F$1,TKB_HK2_Moi_Giang!$L:$L,ThongKe_GV!F$2)>0,"X","") | G24: =IF(COUNTIFS(TKB_HK2_Moi_Giang!$S:$S,ThongKe_GV!$C24,TKB_HK2_Moi_Giang!$K:$K,ThongKe_GV!G$1,TKB_HK2_Moi_Giang!$L:$L,ThongKe_GV!G$2)>0,"X","") | H24: =IF(COUNTIFS(TKB_HK2_Moi_Giang!$S:$S,ThongKe_GV!$C24,TKB_HK2_Moi_Giang!$K:$K,ThongKe_GV!H$1,TKB_HK2_Moi_Giang!$L:$L,ThongKe_GV!H$2)>0,"X","") | I24: =IF(COUNTIFS(TKB_HK2_Moi_Giang!$S:$S,ThongKe_GV!$C24,TKB_HK2_Moi_Giang!$K:$K,ThongKe_GV!I$1,TKB_HK2_Moi_Giang!$L:$L,ThongKe_GV!I$2)>0,"X","") | J24: =IF(COUNTIFS(TKB_HK2_Moi_Giang!$S:$S,ThongKe_GV!$C24,TKB_HK2_Moi_Giang!$K:$K,ThongKe_GV!J$1,TKB_HK2_Moi_Giang!$L:$L,ThongKe_GV!J$2)>0,"X","") | K24: =IF(COUNTIFS(TKB_HK2_Moi_Giang!$S:$S,ThongKe_GV!$C24,TKB_HK2_Moi_Giang!$K:$K,ThongKe_GV!K$1,TKB_HK2_Moi_Giang!$L:$L,ThongKe_GV!K$2)>0,"X","") | L24: =IF(COUNTIFS(TKB_HK2_Moi_Giang!$S:$S,ThongKe_GV!$C24,TKB_HK2_Moi_Giang!$K:$K,ThongKe_GV!L$1,TKB_HK2_Moi_Giang!$L:$L,ThongKe_GV!L$2)>0,"X","") | ... AB24: =IF(COUNTIFS(TKB_HK2_Moi_Giang!$S:$S,ThongKe_GV!$C24,TKB_HK2_Moi_Giang!$K:$K,ThongKe_GV!AB$1,TKB_HK2_Moi_Giang!$L:$L,ThongKe_GV!AB$2)>0,"X","")
A25: =IF(MID(B25,4,1)="Q","Quản trị",IF(MID(B25,4,1)="T","Thiết kế",IF(MID(B25,4,1)="N","Ngoại ngữ",IF(MID(B25,4,1)="C","Công nghệ",IF(MID(B25,4,1)="Y","Y dược",IF(MID(B25,4,1)="V","Văn hóa","")))))) -> Công nghệ | B25: TG-CNTT11 | C25: Trần Ngọc Dân | D25: ngocdancntt@gmail.com | E25: =IF(COUNTIFS(TKB_HK2_Moi_Giang!$S:$S,ThongKe_GV!$C25,TKB_HK2_Moi_Giang!$K:$K,ThongKe_GV!E$1,TKB_HK2_Moi_Giang!$L:$L,ThongKe_GV!E$2)>0,"X","") | F25: =IF(COUNTIFS(TKB_HK2_Moi_Giang!$S:$S,ThongKe_GV!$C25,TKB_HK2_Moi_Giang!$K:$K,ThongKe_GV!F$1,TKB_HK2_Moi_Giang!$L:$L,ThongKe_GV!F$2)>0,"X","") | G25: =IF(COUNTIFS(TKB_HK2_Moi_Giang!$S:$S,ThongKe_GV!$C25,TKB_HK2_Moi_Giang!$K:$K,ThongKe_GV!G$1,TKB_HK2_Moi_Giang!$L:$L,ThongKe_GV!G$2)>0,"X","") | H25: =IF(COUNTIFS(TKB_HK2_Moi_Giang!$S:$S,ThongKe_GV!$C25,TKB_HK2_Moi_Giang!$K:$K,ThongKe_GV!H$1,TKB_HK2_Moi_Giang!$L:$L,ThongKe_GV!H$2)>0,"X","") | I25: =IF(COUNTIFS(TKB_HK2_Moi_Giang!$S:$S,ThongKe_GV!$C25,TKB_HK2_Moi_Giang!$K:$K,ThongKe_GV!I$1,TKB_HK2_Moi_Giang!$L:$L,ThongKe_GV!I$2)>0,"X","") | J25: =IF(COUNTIFS(TKB_HK2_Moi_Giang!$S:$S,ThongKe_GV!$C25,TKB_HK2_Moi_Giang!$K:$K,ThongKe_GV!J$1,TKB_HK2_Moi_Giang!$L:$L,ThongKe_GV!J$2)>0,"X","") | K25: =IF(COUNTIFS(TKB_HK2_Moi_Giang!$S:$S,ThongKe_GV!$C25,TKB_HK2_Moi_Giang!$K:$K,ThongKe_GV!K$1,TKB_HK2_Moi_Giang!$L:$L,ThongKe_GV!K$2)>0,"X","") | L25: =IF(COUNTIFS(TKB_HK2_Moi_Giang!$S:$S,ThongKe_GV!$C25,TKB_HK2_Moi_Giang!$K:$K,ThongKe_GV!L$1,TKB_HK2_Moi_Giang!$L:$L,ThongKe_GV!L$2)>0,"X","") | ... AB25: =IF(COUNTIFS(TKB_HK2_Moi_Giang!$S:$S,ThongKe_GV!$C25,TKB_HK2_Moi_Giang!$K:$K,ThongKe_GV!AB$1,TKB_HK2_Moi_Giang!$L:$L,ThongKe_GV!AB$2)>0,"X","")
A26: =IF(MID(B26,4,1)="Q","Quản trị",IF(MID(B26,4,1)="T","Thiết kế",IF(MID(B26,4,1)="N","Ngoại ngữ",IF(MID(B26,4,1)="C","Công nghệ",IF(MID(B26,4,1)="Y","Y dược",IF(MID(B26,4,1)="V","Văn hóa","")))))) -> Ngoại ngữ | B26: TG-NN48 | C26: Nguyễn Thị Mạnh Hà | D26: riv.nguyen@gmail.com | E26: =IF(COUNTIFS(TKB_HK2_Moi_Giang!$S:$S,ThongKe_GV!$C26,TKB_HK2_Moi_Giang!$K:$K,ThongKe_GV!E$1,TKB_HK2_Moi_Giang!$L:$L,ThongKe_GV!E$2)>0,"X","") | F26: =IF(COUNTIFS(TKB_HK2_Moi_Giang!$S:$S,ThongKe_GV!$C26,TKB_HK2_Moi_Giang!$K:$K,ThongKe_GV!F$1,TKB_HK2_Moi_Giang!$L:$L,ThongKe_GV!F$2)>0,"X","") | G26: =IF(COUNTIFS(TKB_HK2_Moi_Giang!$S:$S,ThongKe_GV!$C26,TKB_HK2_Moi_Giang!$K:$K,ThongKe_GV!G$1,TKB_HK2_Moi_Giang!$L:$L,ThongKe_GV!G$2)>0,"X","") | H26: =IF(COUNTIFS(TKB_HK2_Moi_Giang!$S:$S,ThongKe_GV!$C26,TKB_HK2_Moi_Giang!$K:$K,ThongKe_GV!H$1,TKB_HK2_Moi_Giang!$L:$L,ThongKe_GV!H$2)>0,"X","") | I26: =IF(COUNTIFS(TKB_HK2_Moi_Giang!$S:$S,ThongKe_GV!$C26,TKB_HK2_Moi_Giang!$K:$K,ThongKe_GV!I$1,TKB_HK2_Moi_Giang!$L:$L,ThongKe_GV!I$2)>0,"X","") | J26: =IF(COUNTIFS(TKB_HK2_Moi_Giang!$S:$S,ThongKe_GV!$C26,TKB_HK2_Moi_Giang!$K:$K,ThongKe_GV!J$1,TKB_HK2_Moi_Giang!$L:$L,ThongKe_GV!J$2)>0,"X","") | K26: =IF(COUNTIFS(TKB_HK2_Moi_Giang!$S:$S,ThongKe_GV!$C26,TKB_HK2_Moi_Giang!$K:$K,ThongKe_GV!K$1,TKB_HK2_Moi_Giang!$L:$L,ThongKe_GV!K$2)>0,"X","") | L26: =IF(COUNTIFS(TKB_HK2_Moi_Giang!$S:$S,ThongKe_GV!$C26,TKB_HK2_Moi_Giang!$K:$K,ThongKe_GV!L$1,TKB_HK2_Moi_Giang!$L:$L,ThongKe_GV!L$2)>0,"X","") | ... AB26: =IF(COUNTIFS(TKB_HK2_Moi_Giang!$S:$S,ThongKe_GV!$C26,TKB_HK2_Moi_Giang!$K:$K,ThongKe_GV!AB$1,TKB_HK2_Moi_Giang!$L:$L,ThongKe_GV!AB$2)>0,"X","")
A27: =IF(MID(B27,4,1)="Q","Quản trị",IF(MID(B27,4,1)="T","Thiết kế",IF(MID(B27,4,1)="N","Ngoại ngữ",IF(MID(B27,4,1)="C","Công nghệ",IF(MID(B27,4,1)="Y","Y dược",IF(MID(B27,4,1)="V","Văn hóa","")))))) -> Thiết kế | B27: TG-TK51 | C27: Phạm Đỗ Hoàng An | D27: anphamdo.hcm@gmail.com | E27: =IF(COUNTIFS(TKB_HK2_Moi_Giang!$S:$S,ThongKe_GV!$C27,TKB_HK2_Moi_Giang!$K:$K,ThongKe_GV!E$1,TKB_HK2_Moi_Giang!$L:$L,ThongKe_GV!E$2)>0,"X","") | F27: =IF(COUNTIFS(TKB_HK2_Moi_Giang!$S:$S,ThongKe_GV!$C27,TKB_HK2_Moi_Giang!$K:$K,ThongKe_GV!F$1,TKB_HK2_Moi_Giang!$L:$L,ThongKe_GV!F$2)>0,"X","") | G27: =IF(COUNTIFS(TKB_HK2_Moi_Giang!$S:$S,ThongKe_GV!$C27,TKB_HK2_Moi_Giang!$K:$K,ThongKe_GV!G$1,TKB_HK2_Moi_Giang!$L:$L,ThongKe_GV!G$2)>0,"X","") | H27: =IF(COUNTIFS(TKB_HK2_Moi_Giang!$S:$S,ThongKe_GV!$C27,TKB_HK2_Moi_Giang!$K:$K,ThongKe_GV!H$1,TKB_HK2_Moi_Giang!$L:$L,ThongKe_GV!H$2)>0,"X","") | I27: =IF(COUNTIFS(TKB_HK2_Moi_Giang!$S:$S,ThongKe_GV!$C27,TKB_HK2_Moi_Giang!$K:$K,ThongKe_GV!I$1,TKB_HK2_Moi_Giang!$L:$L,ThongKe_GV!I$2)>0,"X","") | J27: =IF(COUNTIFS(TKB_HK2_Moi_Giang!$S:$S,ThongKe_GV!$C27,TKB_HK2_Moi_Giang!$K:$K,ThongKe_GV!J$1,TKB_HK2_Moi_Giang!$L:$L,ThongKe_GV!J$2)>0,"X","") | K27: =IF(COUNTIFS(TKB_HK2_Moi_Giang!$S:$S,ThongKe_GV!$C27,TKB_HK2_Moi_Giang!$K:$K,ThongKe_GV!K$1,TKB_HK2_Moi_Giang!$L:$L,ThongKe_GV!K$2)>0,"X","") | L27: =IF(COUNTIFS(TKB_HK2_Moi_Giang!$S:$S,ThongKe_GV!$C27,TKB_HK2_Moi_Giang!$K:$K,ThongKe_GV!L$1,TKB_HK2_Moi_Giang!$L:$L,ThongKe_GV!L$2)>0,"X","") | ... AB27: =IF(COUNTIFS(TKB_HK2_Moi_Giang!$S:$S,ThongKe_GV!$C27,TKB_HK2_Moi_Giang!$K:$K,ThongKe_GV!AB$1,TKB_HK2_Moi_Giang!$L:$L,ThongKe_GV!AB$2)>0,"X","")
A28: Ngoại ngữ | B28: CH-TA003 | C28: Văng Công Nghiêm | D28: nghiem.vang@caodangvietmy.edu.vn | E28: =IF(COUNTIFS(TKB_HK2_Moi_Giang!$S:$S,ThongKe_GV!$C28,TKB_HK2_Moi_Giang!$K:$K,ThongKe_GV!E$1,TKB_HK2_Moi_Giang!$L:$L,ThongKe_GV!E$2)>0,"X","") | F28: =IF(COUNTIFS(TKB_HK2_Moi_Giang!$S:$S,ThongKe_GV!$C28,TKB_HK2_Moi_Giang!$K:$K,ThongKe_GV!F$1,TKB_HK2_Moi_Giang!$L:$L,ThongKe_GV!F$2)>0,"X","") | G28: =IF(COUNTIFS(TKB_HK2_Moi_Giang!$S:$S,ThongKe_GV!$C28,TKB_HK2_Moi_Giang!$K:$K,ThongKe_GV!G$1,TKB_HK2_Moi_Giang!$L:$L,ThongKe_GV!G$2)>0,"X","") | H28: =IF(COUNTIFS(TKB_HK2_Moi_Giang!$S:$S,ThongKe_GV!$C28,TKB_HK2_Moi_Giang!$K:$K,ThongKe_GV!H$1,TKB_HK2_Moi_Giang!$L:$L,ThongKe_GV!H$2)>0,"X","") | I28: =IF(COUNTIFS(TKB_HK2_Moi_Giang!$S:$S,ThongKe_GV!$C28,TKB_HK2_Moi_Giang!$K:$K,ThongKe_GV!I$1,TKB_HK2_Moi_Giang!$L:$L,ThongKe_GV!I$2)>0,"X","") | J28: =IF(COUNTIFS(TKB_HK2_Moi_Giang!$S:$S,ThongKe_GV!$C28,TKB_HK2_Moi_Giang!$K:$K,ThongKe_GV!J$1,TKB_HK2_Moi_Giang!$L:$L,ThongKe_GV!J$2)>0,"X","") | K28: =IF(COUNTIFS(TKB_HK2_Moi_Giang!$S:$S,ThongKe_GV!$C28,TKB_HK2_Moi_Giang!$K:$K,ThongKe_GV!K$1,TKB_HK2_Moi_Giang!$L:$L,ThongKe_GV!K$2)>0,"X","") | L28: =IF(COUNTIFS(TKB_HK2_Moi_Giang!$S:$S,ThongKe_GV!$C28,TKB_HK2_Moi_Giang!$K:$K,ThongKe_GV!L$1,TKB_HK2_Moi_Giang!$L:$L,ThongKe_GV!L$2)>0,"X","") | ... AB28: =IF(COUNTIFS(TKB_HK2_Moi_Giang!$S:$S,ThongKe_GV!$C28,TKB_HK2_Moi_Giang!$K:$K,ThongKe_GV!AB$1,TKB_HK2_Moi_Giang!$L:$L,ThongKe_GV!AB$2)>0,"X","")
A29: =IF(MID(B29,4,1)="Q","Quản trị",IF(MID(B29,4,1)="T","Thiết kế",IF(MID(B29,4,1)="N","Ngoại ngữ",IF(MID(B29,4,1)="C","Công nghệ",IF(MID(B29,4,1)="Y","Y dược",IF(MID(B29,4,1)="V","Văn hóa","")))))) -> Văn hóa | B29: TG-VH015 | C29: Lư Thanh Vọng | D29: pyputhvong@gmail.com | E29: =IF(COUNTIFS(TKB_HK2_Moi_Giang!$S:$S,ThongKe_GV!$C29,TKB_HK2_Moi_Giang!$K:$K,ThongKe_GV!E$1,TKB_HK2_Moi_Giang!$L:$L,ThongKe_GV!E$2)>0,"X","") | F29: =IF(COUNTIFS(TKB_HK2_Moi_Giang!$S:$S,ThongKe_GV!$C29,TKB_HK2_Moi_Giang!$K:$K,ThongKe_GV!F$1,TKB_HK2_Moi_Giang!$L:$L,ThongKe_GV!F$2)>0,"X","") | G29: =IF(COUNTIFS(TKB_HK2_Moi_Giang!$S:$S,ThongKe_GV!$C29,TKB_HK2_Moi_Giang!$K:$K,ThongKe_GV!G$1,TKB_HK2_Moi_Giang!$L:$L,ThongKe_GV!G$2)>0,"X","") | H29: =IF(COUNTIFS(TKB_HK2_Moi_Giang!$S:$S,ThongKe_GV!$C29,TKB_HK2_Moi_Giang!$K:$K,ThongKe_GV!H$1,TKB_HK2_Moi_Giang!$L:$L,ThongKe_GV!H$2)>0,"X","") | I29: =IF(COUNTIFS(TKB_HK2_Moi_Giang!$S:$S,ThongKe_GV!$C29,TKB_HK2_Moi_Giang!$K:$K,ThongKe_GV!I$1,TKB_HK2_Moi_Giang!$L:$L,ThongKe_GV!I$2)>0,"X","") | J29: =IF(COUNTIFS(TKB_HK2_Moi_Giang!$S:$S,ThongKe_GV!$C29,TKB_HK2_Moi_Giang!$K:$K,ThongKe_GV!J$1,TKB_HK2_Moi_Giang!$L:$L,ThongKe_GV!J$2)>0,"X","") | K29: =IF(COUNTIFS(TKB_HK2_Moi_Giang!$S:$S,ThongKe_GV!$C29,TKB_HK2_Moi_Giang!$K:$K,ThongKe_GV!K$1,TKB_HK2_Moi_Giang!$L:$L,ThongKe_GV!K$2)>0,"X","") | L29: =IF(COUNTIFS(TKB_HK2_Moi_Giang!$S:$S,ThongKe_GV!$C29,TKB_HK2_Moi_Giang!$K:$K,ThongKe_GV!L$1,TKB_HK2_Moi_Giang!$L:$L,ThongKe_GV!L$2)>0,"X","") | ... AB29: =IF(COUNTIFS(TKB_HK2_Moi_Giang!$S:$S,ThongKe_GV!$C29,TKB_HK2_Moi_Giang!$K:$K,ThongKe_GV!AB$1,TKB_HK2_Moi_Giang!$L:$L,ThongKe_GV!AB$2)>0,"X","")
A30: =IF(MID(B30,4,1)="Q","Quản trị",IF(MID(B30,4,1)="T","Thiết kế",IF(MID(B30,4,1)="N","Ngoại ngữ",IF(MID(B30,4,1)="C","Công nghệ",IF(MID(B30,4,1)="Y","Y dược",IF(MID(B30,4,1)="V","Văn hóa","")))))) -> Y dược | B30: TG-YD056 | C30: Nguyễn Bửu Tân | D30: nguyenbuutan2018@gmail.com | E30: =IF(COUNTIFS(TKB_HK2_Moi_Giang!$S:$S,ThongKe_GV!$C30,TKB_HK2_Moi_Giang!$K:$K,ThongKe_GV!E$1,TKB_HK2_Moi_Giang!$L:$L,ThongKe_GV!E$2)>0,"X","") | F30: =IF(COUNTIFS(TKB_HK2_Moi_Giang!$S:$S,ThongKe_GV!$C30,TKB_HK2_Moi_Giang!$K:$K,ThongKe_GV!F$1,TKB_HK2_Moi_Giang!$L:$L,ThongKe_GV!F$2)>0,"X","") | G30: =IF(COUNTIFS(TKB_HK2_Moi_Giang!$S:$S,ThongKe_GV!$C30,TKB_HK2_Moi_Giang!$K:$K,ThongKe_GV!G$1,TKB_HK2_Moi_Giang!$L:$L,ThongKe_GV!G$2)>0,"X","") | H30: =IF(COUNTIFS(TKB_HK2_Moi_Giang!$S:$S,ThongKe_GV!$C30,TKB_HK2_Moi_Giang!$K:$K,ThongKe_GV!H$1,TKB_HK2_Moi_Giang!$L:$L,ThongKe_GV!H$2)>0,"X","") | I30: =IF(COUNTIFS(TKB_HK2_Moi_Giang!$S:$S,ThongKe_GV!$C30,TKB_HK2_Moi_Giang!$K:$K,ThongKe_GV!I$1,TKB_HK2_Moi_Giang!$L:$L,ThongKe_GV!I$2)>0,"X","") | J30: =IF(COUNTIFS(TKB_HK2_Moi_Giang!$S:$S,ThongKe_GV!$C30,TKB_HK2_Moi_Giang!$K:$K,ThongKe_GV!J$1,TKB_HK2_Moi_Giang!$L:$L,ThongKe_GV!J$2)>0,"X","") | K30: =IF(COUNTIFS(TKB_HK2_Moi_Giang!$S:$S,ThongKe_GV!$C30,TKB_HK2_Moi_Giang!$K:$K,ThongKe_GV!K$1,TKB_HK2_Moi_Giang!$L:$L,ThongKe_GV!K$2)>0,"X","") | L30: =IF(COUNTIFS(TKB_HK2_Moi_Giang!$S:$S,ThongKe_GV!$C30,TKB_HK2_Moi_Giang!$K:$K,ThongKe_GV!L$1,TKB_HK2_Moi_Giang!$L:$L,ThongKe_GV!L$2)>0,"X","") | ... AB30: =IF(COUNTIFS(TKB_HK2_Moi_Giang!$S:$S,ThongKe_GV!$C30,TKB_HK2_Moi_Giang!$K:$K,ThongKe_GV!AB$1,TKB_HK2_Moi_Giang!$L:$L,ThongKe_GV!AB$2)>0,"X","")
A31: =IF(MID(B31,4,1)="Q","Quản trị",IF(MID(B31,4,1)="T","Thiết kế",IF(MID(B31,4,1)="N","Ngoại ngữ",IF(MID(B31,4,1)="C","Công nghệ",IF(MID(B31,4,1)="Y","Y dược",IF(MID(B31,4,1)="V","Văn hóa","")))))) -> Y dược | B31: TG-YD39 | C31: Trần Thị Quy | D31: tranthiquy46@yahoo.com | E31: =IF(COUNTIFS(TKB_HK2_Moi_Giang!$S:$S,ThongKe_GV!$C31,TKB_HK2_Moi_Giang!$K:$K,ThongKe_GV!E$1,TKB_HK2_Moi_Giang!$L:$L,ThongKe_GV!E$2)>0,"X","") | F31: =IF(COUNTIFS(TKB_HK2_Moi_Giang!$S:$S,ThongKe_GV!$C31,TKB_HK2_Moi_Giang!$K:$K,ThongKe_GV!F$1,TKB_HK2_Moi_Giang!$L:$L,ThongKe_GV!F$2)>0,"X","") | G31: =IF(COUNTIFS(TKB_HK2_Moi_Giang!$S:$S,ThongKe_GV!$C31,TKB_HK2_Moi_Giang!$K:$K,ThongKe_GV!G$1,TKB_HK2_Moi_Giang!$L:$L,ThongKe_GV!G$2)>0,"X","") | H31: =IF(COUNTIFS(TKB_HK2_Moi_Giang!$S:$S,ThongKe_GV!$C31,TKB_HK2_Moi_Giang!$K:$K,ThongKe_GV!H$1,TKB_HK2_Moi_Giang!$L:$L,ThongKe_GV!H$2)>0,"X","") | I31: =IF(COUNTIFS(TKB_HK2_Moi_Giang!$S:$S,ThongKe_GV!$C31,TKB_HK2_Moi_Giang!$K:$K,ThongKe_GV!I$1,TKB_HK2_Moi_Giang!$L:$L,ThongKe_GV!I$2)>0,"X","") | J31: =IF(COUNTIFS(TKB_HK2_Moi_Giang!$S:$S,ThongKe_GV!$C31,TKB_HK2_Moi_Giang!$K:$K,ThongKe_GV!J$1,TKB_HK2_Moi_Giang!$L:$L,ThongKe_GV!J$2)>0,"X","") | K31: =IF(COUNTIFS(TKB_HK2_Moi_Giang!$S:$S,ThongKe_GV!$C31,TKB_HK2_Moi_Giang!$K:$K,ThongKe_GV!K$1,TKB_HK2_Moi_Giang!$L:$L,ThongKe_GV!K$2)>0,"X","") | L31: =IF(COUNTIFS(TKB_HK2_Moi_Giang!$S:$S,ThongKe_GV!$C31,TKB_HK2_Moi_Giang!$K:$K,ThongKe_GV!L$1,TKB_HK2_Moi_Giang!$L:$L,ThongKe_GV!L$2)>0,"X","") | ... AB31: =IF(COUNTIFS(TKB_HK2_Moi_Giang!$S:$S,ThongKe_GV!$C31,TKB_HK2_Moi_Giang!$K:$K,ThongKe_GV!AB$1,TKB_HK2_Moi_Giang!$L:$L,ThongKe_GV!AB$2)>0,"X","")
